Workbook
Name A: ABH!$C$149:$I$152
Name AT: #REF!
Name K: ABH!$I$68:$O$80
Name KT: ABH!$C$93:$O$99
Name PE: ABH!$C$23:$I$27
Name Q: ABH!$I$51:$O$63
Name QT: #REF!
Name S: #REF!
Name U: #REF!
Name V: ABH!$C$118:$I$121
Name V_Q: #REF!
Name W_K: ABH!$C$68:$G$80
Name W_Q: ABH!$C$51:$G$63
Name W_S: #REF!
Name W_V: ABH!$C$85:$G$88
Name X: ABH!$C$42:$I$46
Name X_: #REF!
Name Y: #REF!

Sheet Design2
A1: In | B1: Ops | C1: Out | E1: 👇 Check ABH sheet.
A2: X=Friends | B2: Embed | C2: X, dim d=5 | D2: ✓
A3: X | B3: PE+ | C3: X | D3: ✓
A4: X | B4: L2-Normalize | C4: X | D4: ✓
A5: X | B5: W_Q* | C5: Q, dim dq=13 | D5: ✓
A6: X | B6: W_K* | C6: K, dim dk=13 | D6: ✓
A7: X | B7: W_V* | C7: V, dim dv=4 | D7: ✓
A8: Q | B8: K^T* | C8: A | D8: ✓
A9: A | B9: L1-Normalize | C9: A | D9: ✓
A10: A | B10: V* | C10: A | D10: ✓
A11: A | B11: Layer-Norm | C11: A | D11: ✓
A12: A | B12: Softmax | C12: A | D12: ✓

Sheet ABH
C2: X
C3: F | D3: r | E3: i | F3: e | G3: n | H3: d | I3: s
C5: Token ID
C6: {=CODE(LOWER(ABH!C3:I3))- CODE("a")} -> 5 | D6: 17 | E6: 8 | F6: 4 | G6: 13 | H6: 3 | I6: 18 | L6: X = torch.tensor([5, 17, 8, 4, 13, 3, 18])
C8: # 1 | D8: Embed
C10: X = Embed (X)
C11: {=_xlfn.RANDARRAY(5, 7, -1, 1)} -> 0.30929212 | D11: 0.083692576 | E11: 0.89701443 | F11: 0.55859979 | G11: 0.66817858 | H11: 0.2410285 | I11: -0.28737667 | L11: X = nn.Embedding((26, 5)(X)
C12: -0.21355235 | D12: 0.36019142 | E12: -0.34897664 | F12: 0.26477491 | G12: -0.79442526 | H12: -0.92910452 | I12: -0.72195112
C13: -0.42407404 | D13: -0.19683381 | E13: -0.30185132 | F13: -0.32586139 | G13: 0.43338547 | H13: 0.8529103 | I13: -0.97107355
C14: 0.88246238 | D14: -0.77177244 | E14: -0.80427434 | F14: -0.74357995 | G14: 0.18846168 | H14: -0.52866789 | I14: -0.78294829
C15: -0.37642119 | D15: -0.8794761 | E15: -0.78129449 | F15: -0.6857303 | G15: -0.36438409 | H15: 0.095108895 | I15: -0.37257389
C17: # 2 | D17: PE+
C19: Positions
C20: {=_xlfn.SEQUENCE(1, 7, 0)} -> 0 | D20: 1 | E20: 2 | F20: 3 | G20: 4 | H20: 5 | I20: 6
C22: PE
C23: {=_xlfn.RANDARRAY(5, 7, -1, 1)} -> 0.068406679 | D23: -0.3273223 | E23: 0.61434665 | F23: 0.4710603 | G23: 0.30786577 | H23: 0.65266326 | I23: 0.32923579
C24: -0.57473169 | D24: 0.62094164 | E24: -0.62422173 | F24: 0.66214836 | G24: -0.85836256 | H24: 0.20490013 | I24: -0.5045059
C25: 0.40716555 | D25: 0.17553219 | E25: -0.94084146 | F25: -0.76271399 | G25: -0.30242156 | H25: -0.44124434 | I25: -0.061469567
C26: -0.7573705 | D26: -0.23303608 | E26: 0.45647242 | F26: -0.16650351 | G26: 0.22137731 | H26: 0.10923503 | I26: -0.19595285
C27: 0.0050551625 | D27: 0.97409254 | E27: 0.47544766 | F27: -0.97476026 | G27: -0.40541404 | H27: 0.48416553 | I27: 0.40770084
C29: X = PE+ (X)
C30: {=ABH!C11:I15+ABH!C23:I27} -> 0.3776988 | D30: -0.24362973 | E30: 1.5113611 | F30: 1.0296601 | G30: 0.97604434 | H30: 0.89369176 | I30: 0.041859123
C31: -0.78828404 | D31: 0.98113307 | E31: -0.97319837 | F31: 0.92692327 | G31: -1.6527878 | H31: -0.72420439 | I31: -1.226457
C32: -0.016908497 | D32: -0.021301623 | E32: -1.2426928 | F32: -1.0885754 | G32: 0.13096391 | H32: 0.41166596 | I32: -1.0325431
C33: 0.12509188 | D33: -1.0048085 | E33: -0.34780192 | F33: -0.91008347 | G33: 0.40983899 | H33: -0.41943286 | I33: -0.97890114
C34: -0.37136602 | D34: 0.094616443 | E34: -0.30584682 | F34: -1.6604906 | G34: -0.76979813 | H34: 0.57927442 | I34: 0.035126943
C36: # 3 | D36: L2-Normalize
C38: L2
C39: {=_xlfn.BYCOL(ABH!C30:I34, _xlfn.LAMBDA(_xlpm.col, SQRT(SUM(_xlpm.col^2))))} -> 0.95806822 | D39: 1.428644 | E39: 2.2338579 | F39: 2.5864771 | G39: 2.1123633 | H39: 1.4156654 | I39: 1.8792487
C41: X = L2-Normalize (X)
C42: {=ABH!C30:I34/IF(ABH!C39:I39=0,1, ABH!C39:I39)} -> 0.39422954 | D42: -0.17053214 | E42: 0.67656993 | F42: 0.39809364 | G42: 0.46206272 | H42: 0.63128741 | I42: 0.022274392
C43: -0.82278488 | D43: 0.68675825 | E43: -0.43565813 | F43: 0.35837289 | G43: -0.78243539 | H43: -0.51156465 | I43: -0.65263157
C44: -0.017648531 | D44: -0.014910379 | E44: -0.55629894 | F44: -0.42087184 | G44: 0.061998761 | H44: 0.29079326 | I44: -0.54944464
C45: 0.13056678 | D45: -0.70333023 | E45: -0.15569563 | F45: -0.35186218 | G45: 0.19401917 | H45: -0.29627965 | I45: -0.52090026
C46: -0.38761961 | D46: 0.066228145 | E46: -0.13691418 | F46: -0.64198928 | G46: -0.36442506 | H46: 0.40918879 | I46: 0.018692014
C48: # 4 | D48: W_Q*
C50: W_Q | I50: Q = W_Q* (X)
C51: {=_xlfn.RANDARRAY(13, 5, -1, 1)} -> 0.19636244 | D51: -0.23912915 | E51: -0.62187877 | F51: 0.26285488 | G51: 0.40725047 | I51: {=MMULT(ABH!C51:G63,ABH!C42:I46)} -> 0.16160082 | J51: -0.34633991 | K51: 0.48629825 | L51: -0.099734632 | M51: 0.14186577 | N51: 0.15421678 | O51: 0.37281619
C52: 0.76105861 | D52: -0.83667885 | E52: -0.13675185 | F52: 0.038629053 | G52: -0.21231578 | I52: 1.0781934 | J52: -0.7435723 | K52: 0.97854488 | L52: 0.18339693 | M52: 1.0826935 | N52: 0.77037329 | O52: 0.61404222
C53: -0.41739284 | D53: -0.90003922 | E53: 0.80473555 | F53: 0.16841464 | G53: 0.37571432 | I53: 0.43814279 | J53: -0.65249762 | K53: -0.4156216 | L53: -1.1278649 | M53: 0.45700943 | N53: 0.53478533 | O53: 0.055234829
...

Sheet Design3
A1: In | B1: Ops | C1: Out | E1: 👇 Check ABH sheet.
A2: X=Beautiful | B2: Embed | C2: X, dim d=4 | D2: ✓
A3: X | B3: PE+ | C3: X | D3: ✓
A4: X | B4: Layer-Norm | C4: X | D4: ✓
A5: X | B5: W_Q* | C5: Q, dim dq=3 | D5: ✓
A6: X | B6: W_K* | C6: K, dim dk=3 | D6: ✓
A7: X | B7: W_V* | C7: V, dim dv=4 | D7: ✓
A8: Q | B8: K^T* | C8: A | D8: ✓
A9: A | B9: V* | C9: A | D9: ✓
A10: A | B10: Softmax | C10: A | D10: ✓
