Workbook
Name batch: Manual!$D$2
Name dim_0: Manual!$D$3
Name dim_1: Manual!$E$3
Name dim_2: Manual!$F$3
Name dim_3: Manual!$G$3
Name Linear: #REF!
Name tinyDigitsInfo: tinyDigits!$CD$3:$CE$7
Name tinyDigitsSample1: tinyDigits!$C$4:$G$8
Name tinyDigitsSample1: #REF!
Name W: #REF!
Name Weights: Blueprint!$X$61:$AA$70
Name WX: #REF!
Name X: Blueprint!$AC$61:$AF$70
Name Y: Blueprint!$AC$88:$AF$97

Sheet tinyDigits
J1: =OFFSET(Helper!J13,0,1) -> 2
C2: 0 | J2: 1 | Q2: 2 | X2: 3 | AE2: 4 | AL2: 5 | AS2: 6 | AZ2: 7 | BG2: 8 | BN2: 9 | BU2: 10 | CE2: Metadata
B3: 0 | C3: Original | J3: {=INDEX(Helper!$E$13:$E$22, OFFSET(Helper!$J$13,$B3,J$2))} -> Vertical Flip | Q3: {=INDEX(Helper!$E$13:$E$22, OFFSET(Helper!$J$13,$B3,Q$2))} -> Shift Right | X3: {=INDEX(Helper!$E$13:$E$22, OFFSET(Helper!$J$13,$B3,X$2))} -> 90 CCW | AE3: {=INDEX(Helper!$E$13:$E$22, OFFSET(Helper!$J$13,$B3,AE$2))} -> Shift Up | AL3: {=INDEX(Helper!$E$13:$E$22, OFFSET(Helper!$J$13,$B3,AL$2))} -> Shift Down | AS3: {=INDEX(Helper!$E$13:$E$22, OFFSET(Helper!$J$13,$B3,AS$2))} -> Shift Left | AZ3: {=INDEX(Helper!$E$13:$E$22, OFFSET(Helper!$J$13,$B3,AZ$2))} -> 180 Rotation | BG3: {=INDEX(Helper!$E$13:$E$22, OFFSET(Helper!$J$13,$B3,BG$2))} -> Noise | BN3: {=INDEX(Helper!$E$13:$E$22, OFFSET(Helper!$J$13,$B3,BN$2))} -> Horizontal Flip | BU3: {=INDEX(Helper!$E$13:$E$22, OFFSET(Helper!$J$13,$B3,BU$2))} -> 90 CW | CD3: class | CE3: 10
C4: 0.19397269 | D4: 1 | E4: 1 | F4: 1 | G4: 0.23189844 | J4: {=_xlfn.IFS(J3="None", $C4:$G8*0, J3="Horizontal Flip", INDEX($C4:$G8, _xlfn.SEQUENCE(5), 6 - _xlfn.SEQUENCE(1,5)), J3="Vertical Flip", INDEX($C4:$G8, 6 - _xlfn.SEQUENCE(5), _xlfn.SEQUENCE(1,5)), J3="180 Rotation", INDEX($C4:$G8, 6 - _xlfn.SEQUENCE(5), 6 - _xlfn.SEQUENCE(1,5)), J3="90 CW", INDEX($C4:$G8, 6 - _xlfn.SEQUENCE(1,5), _xlfn.SEQUENCE(5)), J3="90 CCW", INDEX($C4:$G8, _xlfn.SEQUENCE(1,5), 6 - _xlfn.SEQUENCE(5)), J3="Shift Up", IF(_xlfn.SEQUENCE(5)+1<=5, INDEX($C4:$G8, _xlfn.SEQUENCE(5)+1, _xlfn.SEQUENCE(1,5)), 0), J3="Shift Down", IF(_xlfn.SEQUENCE(5)-1>=1, INDEX($C4:$G8, _xlfn.SEQUENCE(5)-1, _xlfn.SEQUENCE(1,5)), 0), J3="Shift Left", IF(_xlfn.SEQUENCE(1,5)+1<=5, INDEX($C4:$G8, _xlfn.SEQUENCE(5), _xlfn.SEQUENCE(1,5)+1),0), J3= "Shift Right", IF(_xlfn.SEQUENCE(1,5)-1>=1, INDEX($C4:$G8, _xlfn.SEQUENCE(5), _xlfn.SEQUENCE(1,5)-1), 0), J3="Noise", _xlfn.MAP($C4:$G8 + (_xlfn.RANDARRAY(ROWS($C4:$G8), COLUMNS($C4:$G8)) - 0.5) * 0.4, _xlfn.LAMBDA(_xlpm.x, MAX(0, MIN(1, _xlpm.x)))))} -> 0.63892938 | K4: 0.38883353 | L4: 0.6159387 | M4: 0.64781383 | N4: 0.22260189 | Q4: {=_xlfn.IFS(Q3="None", $C4:$G8*0, Q3="Horizontal Flip", INDEX($C4:$G8, _xlfn.SEQUENCE(5), 6 - _xlfn.SEQUENCE(1,5)), Q3="Vertical Flip", INDEX($C4:$G8, 6 - _xlfn.SEQUENCE(5), _xlfn.SEQUENCE(1,5)), Q3="180 Rotation", INDEX($C4:$G8, 6 - _xlfn.SEQUENCE(5), 6 - _xlfn.SEQUENCE(1,5)), Q3="90 CW", INDEX($C4:$G8, 6 - _xlfn.SEQUENCE(1,5), _xlfn.SEQUENCE(5)), Q3="90 CCW", INDEX($C4:$G8, _xlfn.SEQUENCE(1,5), 6 - _xlfn.SEQUENCE(5)), Q3="Shift Up", IF(_xlfn.SEQUENCE(5)+1<=5, INDEX($C4:$G8, _xlfn.SEQUENCE(5)+1, _xlfn.SEQUENCE(1,5)), 0), Q3="Shift Down", IF(_xlfn.SEQUENCE(5)-1>=1, INDEX($C4:$G8, _xlfn.SEQUENCE(5)-1, _xlfn.SEQUENCE(1,5)), 0), Q3="Shift Left", IF(_xlfn.SEQUENCE(1,5)+1<=5, INDEX($C4:$G8, _xlfn.SEQUENCE(5), _xlfn.SEQUENCE(1,5)+1),0), Q3= "Shift Right", IF(_xlfn.SEQUENCE(1,5)-1>=1, INDEX($C4:$G8, _xlfn.SEQUENCE(5), _xlfn.SEQUENCE(1,5)-1), 0), Q3="Noise", _xlfn.MAP($C4:$G8 + (_xlfn.RANDARRAY(ROWS($C4:$G8), COLUMNS($C4:$G8)) - 0.5) * 0.4, _xlfn.LAMBDA(_xlpm.x, MAX(0, MIN(1, _xlpm.x)))))} -> 0 | R4: 0.19397269 | S4: 1 | T4: 1 | U4: 1 | X4: {=_xlfn.IFS(X3="None", $C4:$G8*0, X3="Horizontal Flip", INDEX($C4:$G8, _xlfn.SEQUENCE(5), 6 - _xlfn.SEQUENCE(1,5)), X3="Vertical Flip", INDEX($C4:$G8, 6 - _xlfn.SEQUENCE(5), _xlfn.SEQUENCE(1,5)), X3="180 Rotation", INDEX($C4:$G8, 6 - _xlfn.SEQUENCE(5), 6 - _xlfn.SEQUENCE(1,5)), X3="90 CW", INDEX($C4:$G8, 6 - _xlfn.SEQUENCE(1,5), _xlfn.SEQUENCE(5)), X3="90 CCW", INDEX($C4:$G8, _xlfn.SEQUENCE(1,5), 6 - _xlfn.SEQUENCE(5)), X3="Shift Up", IF(_xlfn.SEQUENCE(5)+1<=5, INDEX($C4:$G8, _xlfn.SEQUENCE(5)+1, _xlfn.SEQUENCE(1,5)), 0), X3="Shift Down", IF(_xlfn.SEQUENCE(5)-1>=1, INDEX($C4:$G8, _xlfn.SEQUENCE(5)-1, _xlfn.SEQUENCE(1,5)), 0), X3="Shift Left", IF(_xlfn.SEQUENCE(1,5)+1<=5, INDEX($C4:$G8, _xlfn.SEQUENCE(5), _xlfn.SEQUENCE(1,5)+1),0), X3= "Shift Right", IF(_xlfn.SEQUENCE(1,5)-1>=1, INDEX($C4:$G8, _xlfn.SEQUENCE(5), _xlfn.SEQUENCE(1,5)-1), 0), X3="Noise", _xlfn.MAP($C4:$G8 + (_xlfn.RANDARRAY(ROWS($C4:$G8), COLUMNS($C4:$G8)) - 0.5) * 0.4, _xlfn.LAMBDA(_xlpm.x, MAX(0, MIN(1, _xlpm.x)))))} -> 0.23189844 | Y4: 0.20412302 | Z4: 0.35168989 | AA4: 0.53040139 | AB4: 0.22260189 | AE4: {=_xlfn.IFS(AE3="None", $C4:$G8*0, AE3="Horizontal Flip", INDEX($C4:$G8, _xlfn.SEQUENCE(5), 6 - _xlfn.SEQUENCE(1,5)), AE3="Vertical Flip", INDEX($C4:$G8, 6 - _xlfn.SEQUENCE(5), _xlfn.SEQUENCE(1,5)), AE3="180 Rotation", INDEX($C4:$G8, 6 - _xlfn.SEQUENCE(5), 6 - _xlfn.SEQUENCE(1,5)), AE3="90 CW", INDEX($C4:$G8, 6 - _xlfn.SEQUENCE(1,5), _xlfn.SEQUENCE(5)), AE3="90 CCW", INDEX($C4:$G8, _xlfn.SEQUENCE(1,5), 6 - _xlfn.SEQUENCE(5)), AE3="Shift Up", IF(_xlfn.SEQUENCE(5)+1<=5, INDEX($C4:$G8, _xlfn.SEQUENCE(5)+1, _xlfn.SEQUENCE(1,5)), 0), AE3="Shift Down", IF(_xlfn.SEQUENCE(5)-1>=1, INDEX($C4:$G8, _xlfn.SEQUENCE(5)-1, _xlfn.SEQUENCE(1,5)), 0), AE3="Shift Left", IF(_xlfn.SEQUENCE(1,5)+1<=5, INDEX($C4:$G8, _xlfn.SEQUENCE(5), _xlfn.SEQUENCE(1,5)+1),0), AE3= "Shift Right", IF(_xlfn.SEQUENCE(1,5)-1>=1, INDEX($C4:$G8, _xlfn.SEQUENCE(5), _xlfn.SEQUENCE(1,5)-1), 0), AE3="Noise", _xlfn.MAP($C4:$G8 + (_xlfn.RANDARRAY(ROWS($C4:$G8), COLUMNS($C4:$G8)) - 0.5) * 0.4, _xlfn.LAMBDA(_xlpm.x, MAX(0, MIN(1, _xlpm.x)))))} -> 0.62984699 | AF4: 1 | AG4: 0.29821821 | AH4: 1 | AI4: 0.20412302 | AL4: {=_xlfn.IFS(AL3="None", $C4:$G8*0, AL3="Horizontal Flip", INDEX($C4:$G8, _xlfn.SEQUENCE(5), 6 - _xlfn.SEQUENCE(1,5)), AL3="Vertical Flip", INDEX($C4:$G8, 6 - _xlfn.SEQUENCE(5), _xlfn.SEQUENCE(1,5)), AL3="180 Rotation", INDEX($C4:$G8, 6 - _xlfn.SEQUENCE(5), 6 - _xlfn.SEQUENCE(1,5)), AL3="90 CW", INDEX($C4:$G8, 6 - _xlfn.SEQUENCE(1,5), _xlfn.SEQUENCE(5)), AL3="90 CCW", INDEX($C4:$G8, _xlfn.SEQUENCE(1,5), 6 - _xlfn.SEQUENCE(5)), AL3="Shift Up", IF(_xlfn.SEQUENCE(5)+1<=5, INDEX($C4:$G8, _xlfn.SEQUENCE(5)+1, _xlfn.SEQUENCE(1,5)), 0), AL3="Shift Down", IF(_xlfn.SEQUENCE(5)-1>=1, INDEX($C4:$G8, _xlfn.SEQUENCE(5)-1, _xlfn.SEQUENCE(1,5)), 0), AL3="Shift Left", IF(_xlfn.SEQUENCE(1,5)+1<=5, INDEX($C4:$G8, _xlfn.SEQUENCE(5), _xlfn.SEQUENCE(1,5)+1),0), AL3= "Shift Right", IF(_xlfn.SEQUENCE(1,5)-1>=1, INDEX($C4:$G8, _xlfn.SEQUENCE(5), _xlfn.SEQUENCE(1,5)-1), 0), AL3="Noise", _xlfn.MAP($C4:$G8 + (_xlfn.RANDARRAY(ROWS($C4:$G8), COLUMNS($C4:$G8)) - 0.5) * 0.4, _xlfn.LAMBDA(_xlpm.x, MAX(0, MIN(1, _xlpm.x)))))} -> 0 | AM4: 0 | AN4: 0 | AO4: 0 | AP4: 0 | AS4: {=_xlfn.IFS(AS3="None", $C4:$G8*0, AS3="Horizontal Flip", INDEX($C4:$G8, _xlfn.SEQUENCE(5), 6 - _xlfn.SEQUENCE(1,5)), AS3="Vertical Flip", INDEX($C4:$G8, 6 - _xlfn.SEQUENCE(5), _xlfn.SEQUENCE(1,5)), AS3="180 Rotation", INDEX($C4:$G8, 6 - _xlfn.SEQUENCE(5), 6 - _xlfn.SEQUENCE(1,5)), AS3="90 CW", INDEX($C4:$G8, 6 - _xlfn.SEQUENCE(1,5), _xlfn.SEQUENCE(5)), AS3="90 CCW", INDEX($C4:$G8, _xlfn.SEQUENCE(1,5), 6 - _xlfn.SEQUENCE(5)), AS3="Shift Up", IF(_xlfn.SEQUENCE(5)+1<=5, INDEX($C4:$G8, _xlfn.SEQUENCE(5)+1, _xlfn.SEQUENCE(1,5)), 0), AS3="Shift Down", IF(_xlfn.SEQUENCE(5)-1>=1, INDEX($C4:$G8, _xlfn.SEQUENCE(5)-1, _xlfn.SEQUENCE(1,5)), 0), AS3="Shift Left", IF(_xlfn.SEQUENCE(1,5)+1<=5, INDEX($C4:$G8, _xlfn.SEQUENCE(5), _xlfn.SEQUENCE(1,5)+1),0), AS3= "Shift Right", IF(_xlfn.SEQUENCE(1,5)-1>=1, INDEX($C4:$G8, _xlfn.SEQUENCE(5), _xlfn.SEQUENCE(1,5)-1), 0), AS3="Noise", _xlfn.MAP($C4:$G8 + (_xlfn.RANDARRAY(ROWS($C4:$G8), COLUMNS($C4:$G8)) - 0.5) * 0.4, _xlfn.LAMBDA(_xlpm.x, MAX(0, MIN(1, _xlpm.x)))))} -> 1 | AT4: 1 | AU4: 1 | AV4: 0.23189844 | AW4: 0 | AZ4: {=_xlfn.IFS(AZ3="None", $C4:$G8*0, AZ3="Horizontal Flip", INDEX($C4:$G8, _xlfn.SEQUENCE(5), 6 - _xlfn.SEQUENCE(1,5)), AZ3="Vertical Flip", INDEX($C4:$G8, 6 - _xlfn.SEQUENCE(5), _xlfn.SEQUENCE(1,5)), AZ3="180 Rotation", INDEX($C4:$G8, 6 - _xlfn.SEQUENCE(5), 6 - _xlfn.SEQUENCE(1,5)), AZ3="90 CW", INDEX($C4:$G8, 6 - _xlfn.SEQUENCE(1,5), _xlfn.SEQUENCE(5)), AZ3="90 CCW", INDEX($C4:$G8, _xlfn.SEQUENCE(1,5), 6 - _xlfn.SEQUENCE(5)), AZ3="Shift Up", IF(_xlfn.SEQUENCE(5)+1<=5, INDEX($C4:$G8, _xlfn.SEQUENCE(5)+1, _xlfn.SEQUENCE(1,5)), 0), AZ3="Shift Down", IF(_xlfn.SEQUENCE(5)-1>=1, INDEX($C4:$G8, _xlfn.SEQUENCE(5)-1, _xlfn.SEQUENCE(1,5)), 0), AZ3="Shift Left", IF(_xlfn.SEQUENCE(1,5)+1<=5, INDEX($C4:$G8, _xlfn.SEQUENCE(5), _xlfn.SEQUENCE(1,5)+1),0), AZ3= "Shift Right", IF(_xlfn.SEQUENCE(1,5)-1>=1, INDEX($C4:$G8, _xlfn.SEQUENCE(5), _xlfn.SEQUENCE(1,5)-1), 0), AZ3="Noise", _xlfn.MAP($C4:$G8 + (_xlfn.RANDARRAY(ROWS($C4:$G8), COLUMNS($C4:$G8)) - 0.5) * 0.4, _xlfn.LAMBDA(_xlpm.x, MAX(0, MIN(1, _xlpm.x)))))} -> 0.22260189 | BA4: 0.64781383 | BB4: 0.6159387 | BC4: 0.38883353 | BD4: 0.63892938 | BG4: {=_xlfn.IFS(BG3="None", $C4:$G8*0, BG3="Horizontal Flip", INDEX($C4:$G8, _xlfn.SEQUENCE(5), 6 - _xlfn.SEQUENCE(1,5)), BG3="Vertical Flip", INDEX($C4:$G8, 6 - _xlfn.SEQUENCE(5), _xlfn.SEQUENCE(1,5)), BG3="180 Rotation", INDEX($C4:$G8, 6 - _xlfn.SEQUENCE(5), 6 - _xlfn.SEQUENCE(1,5)), BG3="90 CW", INDEX($C4:$G8, 6 - _xlfn.SEQUENCE(1,5), _xlfn.SEQUENCE(5)), BG3="90 CCW", INDEX($C4:$G8, _xlfn.SEQUENCE(1,5), 6 - _xlfn.SEQUENCE(5)), BG3="Shift Up", IF(_xlfn.SEQUENCE(5)+1<=5, INDEX($C4:$G8, _xlfn.SEQUENCE(5)+1, _xlfn.SEQUENCE(1,5)), 0), BG3="Shift Down", IF(_xlfn.SEQUENCE(5)-1>=1, INDEX($C4:$G8, _xlfn.SEQUENCE(5)-1, _xlfn.SEQUENCE(1,5)), 0), BG3="Shift Left", IF(_xlfn.SEQUENCE(1,5)+1<=5, INDEX($C4:$G8, _xlfn.SEQUENCE(5), _xlfn.SEQUENCE(1,5)+1),0), BG3= "Shift Right", IF(_xlfn.SEQUENCE(1,5)-1>=1, INDEX($C4:$G8, _xlfn.SEQUENCE(5), _xlfn.SEQUENCE(1,5)-1), 0), BG3="Noise", _xlfn.MAP($C4:$G8 + (_xlfn.RANDARRAY(ROWS($C4:$G8), COLUMNS($C4:$G8)) - 0.5) * 0.4, _xlfn.LAMBDA(_xlpm.x, MAX(0, MIN(1, _xlpm.x)))))} -> 0.28825121 | BH4: 0.94840056 | BI4: 0.95564103 | BJ4: 1 | BK4: 0.24367981 | BN4: {=_xlfn.IFS(BN3="None", $C4:$G8*0, BN3="Horizontal Flip", INDEX($C4:$G8, _xlfn.SEQUENCE(5), 6 - _xlfn.SEQUENCE(1,5)), BN3="Vertical Flip", INDEX($C4:$G8, 6 - _xlfn.SEQUENCE(5), _xlfn.SEQUENCE(1,5)), BN3="180 Rotation", INDEX($C4:$G8, 6 - _xlfn.SEQUENCE(5), 6 - _xlfn.SEQUENCE(1,5)), BN3="90 CW", INDEX($C4:$G8, 6 - _xlfn.SEQUENCE(1,5), _xlfn.SEQUENCE(5)), BN3="90 CCW", INDEX($C4:$G8, _xlfn.SEQUENCE(1,5), 6 - _xlfn.SEQUENCE(5)), BN3="Shift Up", IF(_xlfn.SEQUENCE(5)+1<=5, INDEX($C4:$G8, _xlfn.SEQUENCE(5)+1, _xlfn.SEQUENCE(1,5)), 0), BN3="Shift Down", IF(_xlfn.SEQUENCE(5)-1>=1, INDEX($C4:$G8, _xlfn.SEQUENCE(5)-1, _xlfn.SEQUENCE(1,5)), 0), BN3="Shift Left", IF(_xlfn.SEQUENCE(1,5)+1<=5, INDEX($C4:$G8, _xlfn.SEQUENCE(5), _xlfn.SEQUENCE(1,5)+1),0), BN3= "Shift Right", IF(_xlfn.SEQUENCE(1,5)-1>=1, INDEX($C4:$G8, _xlfn.SEQUENCE(5), _xlfn.SEQUENCE(1,5)-1), 0), BN3="Noise", _xlfn.MAP($C4:$G8 + (_xlfn.RANDARRAY(ROWS($C4:$G8), COLUMNS($C4:$G8)) - 0.5) * 0.4, _xlfn.LAMBDA(_xlpm.x, MAX(0, MIN(1, _xlpm.x)))))} -> 0.23189844 | BO4: 1 | BP4: 1 | BQ4: 1 | BR4: 0.19397269 | BU4: {=_xlfn.IFS(BU3="None", $C4:$G8*0, BU3="Horizontal Flip", INDEX($C4:$G8, _xlfn.SEQUENCE(5), 6 - _xlfn.SEQUENCE(1,5)), BU3="Vertical Flip", INDEX($C4:$G8, 6 - _xlfn.SEQUENCE(5), _xlfn.SEQUENCE(1,5)), BU3="180 Rotation", INDEX($C4:$G8, 6 - _xlfn.SEQUENCE(5), 6 - _xlfn.SEQUENCE(1,5)), BU3="90 CW", INDEX($C4:$G8, 6 - _xlfn.SEQUENCE(1,5), _xlfn.SEQUENCE(5)), BU3="90 CCW", INDEX($C4:$G8, _xlfn.SEQUENCE(1,5), 6 - _xlfn.SEQUENCE(5)), BU3="Shift Up", IF(_xlfn.SEQUENCE(5)+1<=5, INDEX($C4:$G8, _xlfn.SEQUENCE(5)+1, _xlfn.SEQUENCE(1,5)), 0), BU3="Shift Down", IF(_xlfn.SEQUENCE(5)-1>=1, INDEX($C4:$G8, _xlfn.SEQUENCE(5)-1, _xlfn.SEQUENCE(1,5)), 0), BU3="Shift Left", IF(_xlfn.SEQUENCE(1,5)+1<=5, INDEX($C4:$G8, _xlfn.SEQUENCE(5), _xlfn.SEQUENCE(1,5)+1),0), BU3= "Shift Right", IF(_xlfn.SEQUENCE(1,5)-1>=1, INDEX($C4:$G8, _xlfn.SEQUENCE(5), _xlfn.SEQUENCE(1,5)-1), 0), BU3="Noise", _xlfn.MAP($C4:$G8 + (_xlfn.RANDARRAY(ROWS($C4:$G8), COLUMNS($C4:$G8)) - 0.5) * 0.4, _xlfn.LAMBDA(_xlpm.x, MAX(0, MIN(1, _xlpm.x)))))} -> 0.63892938 | BV4: 0.57347654 | BW4: 0.58778719 | BX4: 0.62984699 | BY4: 0.19397269 | CD4: names | CE4: 0, 1, 2, 3, 4, 5, 6, 7, 8, 9
C5: 0.62984699 | D5: 1 | E5: 0.29821821 | F5: 1 | G5: 0.20412302 | J5: 0.57347654 | K5: 1 | L5: 1 | M5: 1 | N5: 0.53040139 | Q5: 0 | R5: 0.62984699 | S5: 1 | T5: 0.29821821 | U5: 1 | X5: 1 | Y5: 1 | Z5: 1 | AA5: 1 | AB5: 0.64781383 | AE5: 0.58778719 | AF5: 1 | AG5: 0.36306765 | AH5: 1 | AI5: 0.35168989 | AL5: 0.19397269 | AM5: 1 | AN5: 1 | AO5: 1 | AP5: 0.23189844 | AS5: 1 | AT5: 0.29821821 | AU5: 1 | AV5: 0.20412302 | AW5: 0 | AZ5: 0.53040139 | BA5: 1 | BB5: 1 | BC5: 1 | BD5: 0.57347654 | BG5: 0.66375279 | BH5: 1 | BI5: 0.13003226 | BJ5: 1 | BK5: 0.054417978 | BN5: 0.20412302 | BO5: 1 | BP5: 0.29821821 | BQ5: 1 | BR5: 0.62984699 | BU5: 0.38883353 | BV5: 1 | BW5: 1 | BX5: 1 | BY5: 1 | CD5: samples | CE5: 11
C6: 0.58778719 | D6: 1 | E6: 0.36306765 | F6: 1 | G6: 0.35168989 | J6: 0.58778719 | K6: 1 | L6: 0.36306765 | M6: 1 | N6: 0.35168989 | Q6: 0 | R6: 0.58778719 | S6: 1 | T6: 0.36306765 | U6: 1 | X6: 1 | Y6: 0.29821821 | Z6: 0.36306765 | AA6: 1 | AB6: 0.6159387 | AE6: 0.57347654 | AF6: 1 | AG6: 1 | AH6: 1 | AI6: 0.53040139 | AL6: 0.62984699 | AM6: 1 | AN6: 0.29821821 | AO6: 1 | AP6: 0.20412302 | AS6: 1 | AT6: 0.36306765 | AU6: 1 | AV6: 0.35168989 | AW6: 0 | AZ6: 0.35168989 | BA6: 1 | BB6: 0.36306765 | BC6: 1 | BD6: 0.58778719 | BG6: 0.45106541 | BH6: 1 | BI6: 0.47401027 | BJ6: 0.85016637 | BK6: 0.45328994 | BN6: 0.35168989 | BO6: 1 | BP6: 0.36306765 | BQ6: 1 | BR6: 0.58778719 | BU6: 0.6159387 | BV6: 1 | BW6: 0.36306765 | BX6: 0.29821821 | BY6: 1 | CD6: rows | CE6: 5
C7: 0.57347654 | D7: 1 | E7: 1 | F7: 1 | G7: 0.53040139 | J7: 0.62984699 | K7: 1 | L7: 0.29821821 | M7: 1 | N7: 0.20412302 | Q7: 0 | R7: 0.57347654 | S7: 1 | T7: 1 | U7: 1 | X7: 1 | Y7: 1 | Z7: 1 | AA7: 1 | AB7: 0.38883353 | AE7: 0.63892938 | AF7: 0.38883353 | AG7: 0.6159387 | AH7: 0.64781383 | AI7: 0.22260189 | AL7: 0.58778719 | AM7: 1 | AN7: 0.36306765 | AO7: 1 | AP7: 0.35168989 | AS7: 1 | AT7: 1 | AU7: 1 | AV7: 0.53040139 | AW7: 0 | AZ7: 0.20412302 | BA7: 1 | BB7: 0.29821821 | BC7: 1 | BD7: 0.62984699 | BG7: 0.62149275 | BH7: 0.97659091 | BI7: 1 | BJ7: 1 | BK7: 0.62590366 | BN7: 0.53040139 | BO7: 1 | BP7: 1 | BQ7: 1 | BR7: 0.57347654 | BU7: 0.64781383 | BV7: 1 | BW7: 1 | BX7: 1 | BY7: 1 | CD7: cols | CE7: 5
C8: 0.63892938 | D8: 0.38883353 | E8: 0.6159387 | F8: 0.64781383 | G8: 0.22260189 | J8: 0.19397269 | K8: 1 | L8: 1 | M8: 1 | N8: 0.23189844 | Q8: 0 | R8: 0.63892938 | S8: 0.38883353 | T8: 0.6159387 | U8: 0.64781383 | X8: 0.19397269 | Y8: 0.62984699 | Z8: 0.58778719 | AA8: 0.57347654 | AB8: 0.63892938 | AE8: 0 | AF8: 0 | AG8: 0 | AH8: 0 | AI8: 0 | AL8: 0.57347654 | AM8: 1 | AN8: 1 | AO8: 1 | AP8: 0.53040139 | AS8: 0.38883353 | AT8: 0.6159387 | AU8: 0.64781383 | AV8: 0.22260189 | AW8: 0 | AZ8: 0.23189844 | BA8: 1 | BB8: 1 | BC8: 1 | BD8: 0.19397269 | BG8: 0.62391443 | BH8: 0.54867583 | BI8: 0.76793361 | BJ8: 0.59984873 | BK8: 0.32585522 | BN8: 0.22260189 | BO8: 0.64781383 | BP8: 0.6159387 | BQ8: 0.38883353 | BR8: 0.63892938 | BU8: 0.22260189 | BV8: 0.53040139 | BW8: 0.35168989 | BX8: 0.20412302 | BY8: 0.23189844
B10: 1 | C10: Original | J10: {=INDEX(Helper!$E$13:$E$22, OFFSET(Helper!$J$13,$B10,J$2))} -> Vertical Flip | Q10: {=INDEX(Helper!$E$13:$E$22, OFFSET(Helper!$J$13,$B10,Q$2))} -> Horizontal Flip | X10: {=INDEX(Helper!$E$13:$E$22, OFFSET(Helper!$J$13,$B10,X$2))} -> Shift Right | AE10: {=INDEX(Helper!$E$13:$E$22, OFFSET(Helper!$J$13,$B10,AE$2))} -> 90 CW | AL10: {=INDEX(Helper!$E$13:$E$22, OFFSET(Helper!$J$13,$B10,AL$2))} -> Shift Left | AS10: {=INDEX(Helper!$E$13:$E$22, OFFSET(Helper!$J$13,$B10,AS$2))} -> Noise | AZ10: {=INDEX(Helper!$E$13:$E$22, OFFSET(Helper!$J$13,$B10,AZ$2))} -> 180 Rotation | BG10: {=INDEX(Helper!$E$13:$E$22, OFFSET(Helper!$J$13,$B10,BG$2))} -> Shift Down | BN10: {=INDEX(Helper!$E$13:$E$22, OFFSET(Helper!$J$13,$B10,BN$2))} -> 90 CCW | BU10: {=INDEX(Helper!$E$13:$E$22, OFFSET(Helper!$J$13,$B10,BU$2))} -> Shift Up
C11: 0.49852125 | D11: 0.32578389 | E11: 1 | F11: 0.23722851 | G11: 0.57956458 | J11: {=_xlfn.IFS(J10="None", $C11:$G15*0, J10="Horizontal Flip", INDEX($C11:$G15, _xlfn.SEQUENCE(5), 6 - _xlfn.SEQUENCE(1,5)), J10="Vertical Flip", INDEX($C11:$G15, 6 - _xlfn.SEQUENCE(5), _xlfn.SEQUENCE(1,5)), J10="180 Rotation", INDEX($C11:$G15, 6 - _xlfn.SEQUENCE(5), 6 - _xlfn.SEQUENCE(1,5)), J10="90 CW", INDEX($C11:$G15, 6 - _xlfn.SEQUENCE(1,5), _xlfn.SEQUENCE(5)), J10="90 CCW", INDEX($C11:$G15, _xlfn.SEQUENCE(1,5), 6 - _xlfn.SEQUENCE(5)), J10="Shift Up", IF(_xlfn.SEQUENCE(5)+1<=5, INDEX($C11:$G15, _xlfn.SEQUENCE(5)+1, _xlfn.SEQUENCE(1,5)), 0), J10="Shift Down", IF(_xlfn.SEQUENCE(5)-1>=1, INDEX($C11:$G15, _xlfn.SEQUENCE(5)-1, _xlfn.SEQUENCE(1,5)), 0), J10="Shift Left", IF(_xlfn.SEQUENCE(1,5)+1<=5, INDEX($C11:$G15, _xlfn.SEQUENCE(5), _xlfn.SEQUENCE(1,5)+1),0), J10= "Shift Right", IF(_xlfn.SEQUENCE(1,5)-1>=1, INDEX($C11:$G15, _xlfn.SEQUENCE(5), _xlfn.SEQUENCE(1,5)-1), 0), J10="Noise", _xlfn.MAP($C11:$G15 + (_xlfn.RANDARRAY(ROWS($C11:$G15), COLUMNS($C11:$G15)) - 0.5) * 0.4, _xlfn.LAMBDA(_xlpm.x, MAX(0, MIN(1, _xlpm.x)))))} -> 0.33432835 | K11: 1 | L11: 1 | M11: 1 | N11: 0.18222316 | Q11: {=_xlfn.IFS(Q10="None", $C11:$G15*0, Q10="Horizontal Flip", INDEX($C11:$G15, _xlfn.SEQUENCE(5), 6 - _xlfn.SEQUENCE(1,5)), Q10="Vertical Flip", INDEX($C11:$G15, 6 - _xlfn.SEQUENCE(5), _xlfn.SEQUENCE(1,5)), Q10="180 Rotation", INDEX($C11:$G15, 6 - _xlfn.SEQUENCE(5), 6 - _xlfn.SEQUENCE(1,5)), Q10="90 CW", INDEX($C11:$G15, 6 - _xlfn.SEQUENCE(1,5), _xlfn.SEQUENCE(5)), Q10="90 CCW", INDEX($C11:$G15, _xlfn.SEQUENCE(1,5), 6 - _xlfn.SEQUENCE(5)), Q10="Shift Up", IF(_xlfn.SEQUENCE(5)+1<=5, INDEX($C11:$G15, _xlfn.SEQUENCE(5)+1, _xlfn.SEQUENCE(1,5)), 0), Q10="Shift Down", IF(_xlfn.SEQUENCE(5)-1>=1, INDEX($C11:$G15, _xlfn.SEQUENCE(5)-1, _xlfn.SEQUENCE(1,5)), 0), Q10="Shift Left", IF(_xlfn.SEQUENCE(1,5)+1<=5, INDEX($C11:$G15, _xlfn.SEQUENCE(5), _xlfn.SEQUENCE(1,5)+1),0), Q10= "Shift Right", IF(_xlfn.SEQUENCE(1,5)-1>=1, INDEX($C11:$G15, _xlfn.SEQUENCE(5), _xlfn.SEQUENCE(1,5)-1), 0), Q10="Noise", _xlfn.MAP($C11:$G15 + (_xlfn.RANDARRAY(ROWS($C11:$G15), COLUMNS($C11:$G15)) - 0.5) * 0.4, _xlfn.LAMBDA(_xlpm.x, MAX(0, MIN(1, _xlpm.x)))))} -> 0.57956458 | R11: 0.23722851 | S11: 1 | T11: 0.32578389 | U11: 0.49852125 | X11: {=_xlfn.IFS(X10="None", $C11:$G15*0, X10="Horizontal Flip", INDEX($C11:$G15, _xlfn.SEQUENCE(5), 6 - _xlfn.SEQUENCE(1,5)), X10="Vertical Flip", INDEX($C11:$G15, 6 - _xlfn.SEQUENCE(5), _xlfn.SEQUENCE(1,5)), X10="180 Rotation", INDEX($C11:$G15, 6 - _xlfn.SEQUENCE(5), 6 - _xlfn.SEQUENCE(1,5)), X10="90 CW", INDEX($C11:$G15, 6 - _xlfn.SEQUENCE(1,5), _xlfn.SEQUENCE(5)), X10="90 CCW", INDEX($C11:$G15, _xlfn.SEQUENCE(1,5), 6 - _xlfn.SEQUENCE(5)), X10="Shift Up", IF(_xlfn.SEQUENCE(5)+1<=5, INDEX($C11:$G15, _xlfn.SEQUENCE(5)+1, _xlfn.SEQUENCE(1,5)), 0), X10="Shift Down", IF(_xlfn.SEQUENCE(5)-1>=1, INDEX($C11:$G15, _xlfn.SEQUENCE(5)-1, _xlfn.SEQUENCE(1,5)), 0), X10="Shift Left", IF(_xlfn.SEQUENCE(1,5)+1<=5, INDEX($C11:$G15, _xlfn.SEQUENCE(5), _xlfn.SEQUENCE(1,5)+1),0), X10= "Shift Right", IF(_xlfn.SEQUENCE(1,5)-1>=1, INDEX($C11:$G15, _xlfn.SEQUENCE(5), _xlfn.SEQUENCE(1,5)-1), 0), X10="Noise", _xlfn.MAP($C11:$G15 + (_xlfn.RANDARRAY(ROWS($C11:$G15), COLUMNS($C11:$G15)) - 0.5) * 0.4, _xlfn.LAMBDA(_xlpm.x, MAX(0, MIN(1, _xlpm.x)))))} -> 0 | Y11: 0.49852125 | Z11: 0.32578389 | AA11: 1 | AB11: 0.23722851 | AE11: {=_xlfn.IFS(AE10="None", $C11:$G15*0, AE10="Horizontal Flip", INDEX($C11:$G15, _xlfn.SEQUENCE(5), 6 - _xlfn.SEQUENCE(1,5)), AE10="Vertical Flip", INDEX($C11:$G15, 6 - _xlfn.SEQUENCE(5), _xlfn.SEQUENCE(1,5)), AE10="180 Rotation", INDEX($C11:$G15, 6 - _xlfn.SEQUENCE(5), 6 - _xlfn.SEQUENCE(1,5)), AE10="90 CW", INDEX($C11:$G15, 6 - _xlfn.SEQUENCE(1,5), _xlfn.SEQUENCE(5)), AE10="90 CCW", INDEX($C11:$G15, _xlfn.SEQUENCE(1,5), 6 - _xlfn.SEQUENCE(5)), AE10="Shift Up", IF(_xlfn.SEQUENCE(5)+1<=5, INDEX($C11:$G15, _xlfn.SEQUENCE(5)+1, _xlfn.SEQUENCE(1,5)), 0), AE10="Shift Down", IF(_xlfn.SEQUENCE(5)-1>=1, INDEX($C11:$G15, _xlfn.SEQUENCE(5)-1, _xlfn.SEQUENCE(1,5)), 0), AE10="Shift Left", IF(_xlfn.SEQUENCE(1,5)+1<=5, INDEX($C11:$G15, _xlfn.SEQUENCE(5), _xlfn.SEQUENCE(1,5)+1),0), AE10= "Shift Right", IF(_xlfn.SEQUENCE(1,5)-1>=1, INDEX($C11:$G15, _xlfn.SEQUENCE(5), _xlfn.SEQUENCE(1,5)-1), 0), AE10="Noise", _xlfn.MAP($C11:$G15 + (_xlfn.RANDARRAY(ROWS($C11:$G15), COLUMNS($C11:$G15)) - 0.5) * 0.4, _xlfn.LAMBDA(_xlpm.x, MAX(0, MIN(1, _xlpm.x)))))} -> 0.33432835 | AF11: 0.36064882 | AG11: 0.29327062 | AH11: 0.52525198 | AI11: 0.49852125 | AL11: {=_xlfn.IFS(AL10="None", $C11:$G15*0, AL10="Horizontal Flip", INDEX($C11:$G15, _xlfn.SEQUENCE(5), 6 - _xlfn.SEQUENCE(1,5)), AL10="Vertical Flip", INDEX($C11:$G15, 6 - _xlfn.SEQUENCE(5), _xlfn.SEQUENCE(1,5)), AL10="180 Rotation", INDEX($C11:$G15, 6 - _xlfn.SEQUENCE(5), 6 - _xlfn.SEQUENCE(1,5)), AL10="90 CW", INDEX($C11:$G15, 6 - _xlfn.SEQUENCE(1,5), _xlfn.SEQUENCE(5)), AL10="90 CCW", INDEX($C11:$G15, _xlfn.SEQUENCE(1,5), 6 - _xlfn.SEQUENCE(5)), AL10="Shift Up", IF(_xlfn.SEQUENCE(5)+1<=5, INDEX($C11:$G15, _xlfn.SEQUENCE(5)+1, _xlfn.SEQUENCE(1,5)), 0), AL10="Shift Down", IF(_xlfn.SEQUENCE(5)-1>=1, INDEX($C11:$G15, _xlfn.SEQUENCE(5)-1, _xlfn.SEQUENCE(1,5)), 0), AL10="Shift Left", IF(_xlfn.SEQUENCE(1,5)+1<=5, INDEX($C11:$G15, _xlfn.SEQUENCE(5), _xlfn.SEQUENCE(1,5)+1),0), AL10= "Shift Right", IF(_xlfn.SEQUENCE(1,5)-1>=1, INDEX($C11:$G15, _xlfn.SEQUENCE(5), _xlfn.SEQUENCE(1,5)-1), 0), AL10="Noise", _xlfn.MAP($C11:$G15 + (_xlfn.RANDARRAY(ROWS($C11:$G15), COLUMNS($C11:$G15)) - 0.5) * 0.4, _xlfn.LAMBDA(_xlpm.x, MAX(0, MIN(1, _xlpm.x)))))} -> 0.32578389 | AM11: 1 | AN11: 0.23722851 | AO11: 0.57956458 | AP11: 0 | AS11: {=_xlfn.IFS(AS10="None", $C11:$G15*0, AS10="Horizontal Flip", INDEX($C11:$G15, _xlfn.SEQUENCE(5), 6 - _xlfn.SEQUENCE(1,5)), AS10="Vertical Flip", INDEX($C11:$G15, 6 - _xlfn.SEQUENCE(5), _xlfn.SEQUENCE(1,5)), AS10="180 Rotation", INDEX($C11:$G15, 6 - _xlfn.SEQUENCE(5), 6 - _xlfn.SEQUENCE(1,5)), AS10="90 CW", INDEX($C11:$G15, 6 - _xlfn.SEQUENCE(1,5), _xlfn.SEQUENCE(5)), AS10="90 CCW", INDEX($C11:$G15, _xlfn.SEQUENCE(1,5), 6 - _xlfn.SEQUENCE(5)), AS10="Shift Up", IF(_xlfn.SEQUENCE(5)+1<=5, INDEX($C11:$G15, _xlfn.SEQUENCE(5)+1, _xlfn.SEQUENCE(1,5)), 0), AS10="Shift Down", IF(_xlfn.SEQUENCE(5)-1>=1, INDEX($C11:$G15, _xlfn.SEQUENCE(5)-1, _xlfn.SEQUENCE(1,5)), 0), AS10="Shift Left", IF(_xlfn.SEQUENCE(1,5)+1<=5, INDEX($C11:$G15, _xlfn.SEQUENCE(5), _xlfn.SEQUENCE(1,5)+1),0), AS10= "Shift Right", IF(_xlfn.SEQUENCE(1,5)-1>=1, INDEX($C11:$G15, _xlfn.SEQUENCE(5), _xlfn.SEQUENCE(1,5)-1), 0), AS10="Noise", _xlfn.MAP($C11:$G15 + (_xlfn.RANDARRAY(ROWS($C11:$G15), COLUMNS($C11:$G15)) - 0.5) * 0.4, _xlfn.LAMBDA(_xlpm.x, MAX(0, MIN(1, _xlpm.x)))))} -> 0.3449092 | AT11: 0.14503663 | AU11: 1 | AV11: 0.40891999 | AW11: 0.70860841 | AZ11: {=_xlfn.IFS(AZ10="None", $C11:$G15*0, AZ10="Horizontal Flip", INDEX($C11:$G15, _xlfn.SEQUENCE(5), 6 - _xlfn.SEQUENCE(1,5)), AZ10="Vertical Flip", INDEX($C11:$G15, 6 - _xlfn.SEQUENCE(5), _xlfn.SEQUENCE(1,5)), AZ10="180 Rotation", INDEX($C11:$G15, 6 - _xlfn.SEQUENCE(5), 6 - _xlfn.SEQUENCE(1,5)), AZ10="90 CW", INDEX($C11:$G15, 6 - _xlfn.SEQUENCE(1,5), _xlfn.SEQUENCE(5)), AZ10="90 CCW", INDEX($C11:$G15, _xlfn.SEQUENCE(1,5), 6 - _xlfn.SEQUENCE(5)), AZ10="Shift Up", IF(_xlfn.SEQUENCE(5)+1<=5, INDEX($C11:$G15, _xlfn.SEQUENCE(5)+1, _xlfn.SEQUENCE(1,5)), 0), AZ10="Shift Down", IF(_xlfn.SEQUENCE(5)-1>=1, INDEX($C11:$G15, _xlfn.SEQUENCE(5)-1, _xlfn.SEQUENCE(1,5)), 0), AZ10="Shift Left", IF(_xlfn.SEQUENCE(1,5)+1<=5, INDEX($C11:$G15, _xlfn.SEQUENCE(5), _xlfn.SEQUENCE(1,5)+1),0), AZ10= "Shift Right", IF(_xlfn.SEQUENCE(1,5)-1>=1, INDEX($C11:$G15, _xlfn.SEQUENCE(5), _xlfn.SEQUENCE(1,5)-1), 0), AZ10="Noise", _xlfn.MAP($C11:$G15 + (_xlfn.RANDARRAY(ROWS($C11:$G15), COLUMNS($C11:$G15)) - 0.5) * 0.4, _xlfn.LAMBDA(_xlpm.x, MAX(0, MIN(1, _xlpm.x)))))} -> 0.18222316 | BA11: 1 | BB11: 1 | BC11: 1 | BD11: 0.33432835 | BG11: {=_xlfn.IFS(BG10="None", $C11:$G15*0, BG10="Horizontal Flip", INDEX($C11:$G15, _xlfn.SEQUENCE(5), 6 - _xlfn.SEQUENCE(1,5)), BG10="Vertical Flip", INDEX($C11:$G15, 6 - _xlfn.SEQUENCE(5), _xlfn.SEQUENCE(1,5)), BG10="180 Rotation", INDEX($C11:$G15, 6 - _xlfn.SEQUENCE(5), 6 - _xlfn.SEQUENCE(1,5)), BG10="90 CW", INDEX($C11:$G15, 6 - _xlfn.SEQUENCE(1,5), _xlfn.SEQUENCE(5)), BG10="90 CCW", INDEX($C11:$G15, _xlfn.SEQUENCE(1,5), 6 - _xlfn.SEQUENCE(5)), BG10="Shift Up", IF(_xlfn.SEQUENCE(5)+1<=5, INDEX($C11:$G15, _xlfn.SEQUENCE(5)+1, _xlfn.SEQUENCE(1,5)), 0), BG10="Shift Down", IF(_xlfn.SEQUENCE(5)-1>=1, INDEX($C11:$G15, _xlfn.SEQUENCE(5)-1, _xlfn.SEQUENCE(1,5)), 0), BG10="Shift Left", IF(_xlfn.SEQUENCE(1,5)+1<=5, INDEX($C11:$G15, _xlfn.SEQUENCE(5), _xlfn.SEQUENCE(1,5)+1),0), BG10= "Shift Right", IF(_xlfn.SEQUENCE(1,5)-1>=1, INDEX($C11:$G15, _xlfn.SEQUENCE(5), _xlfn.SEQUENCE(1,5)-1), 0), BG10="Noise", _xlfn.MAP($C11:$G15 + (_xlfn.RANDARRAY(ROWS($C11:$G15), COLUMNS($C11:$G15)) - 0.5) * 0.4, _xlfn.LAMBDA(_xlpm.x, MAX(0, MIN(1, _xlpm.x)))))} -> 0 | BH11: 0 | BI11: 0 | BJ11: 0 | BK11: 0 | BN11: {=_xlfn.IFS(BN10="None", $C11:$G15*0, BN10="Horizontal Flip", INDEX($C11:$G15, _xlfn.SEQUENCE(5), 6 - _xlfn.SEQUENCE(1,5)), BN10="Vertical Flip", INDEX($C11:$G15, 6 - _xlfn.SEQUENCE(5), _xlfn.SEQUENCE(1,5)), BN10="180 Rotation", INDEX($C11:$G15, 6 - _xlfn.SEQUENCE(5), 6 - _xlfn.SEQUENCE(1,5)), BN10="90 CW", INDEX($C11:$G15, 6 - _xlfn.SEQUENCE(1,5), _xlfn.SEQUENCE(5)), BN10="90 CCW", INDEX($C11:$G15, _xlfn.SEQUENCE(1,5), 6 - _xlfn.SEQUENCE(5)), BN10="Shift Up", IF(_xlfn.SEQUENCE(5)+1<=5, INDEX($C11:$G15, _xlfn.SEQUENCE(5)+1, _xlfn.SEQUENCE(1,5)), 0), BN10="Shift Down", IF(_xlfn.SEQUENCE(5)-1>=1, INDEX($C11:$G15, _xlfn.SEQUENCE(5)-1, _xlfn.SEQUENCE(1,5)), 0), BN10="Shift Left", IF(_xlfn.SEQUENCE(1,5)+1<=5, INDEX($C11:$G15, _xlfn.SEQUENCE(5), _xlfn.SEQUENCE(1,5)+1),0), BN10= "Shift Right", IF(_xlfn.SEQUENCE(1,5)-1>=1, INDEX($C11:$G15, _xlfn.SEQUENCE(5), _xlfn.SEQUENCE(1,5)-1), 0), BN10="Noise", _xlfn.MAP($C11:$G15 + (_xlfn.RANDARRAY(ROWS($C11:$G15), COLUMNS($C11:$G15)) - 0.5) * 0.4, _xlfn.LAMBDA(_xlpm.x, MAX(0, MIN(1, _xlpm.x)))))} -> 0.57956458 | BO11: 0.62339485 | BP11: 0.44243688 | BQ11: 0.41742635 | BR11: 0.18222316 | BU11: {=_xlfn.IFS(BU10="None", $C11:$G15*0, BU10="Horizontal Flip", INDEX($C11:$G15, _xlfn.SEQUENCE(5), 6 - _xlfn.SEQUENCE(1,5)), BU10="Vertical Flip", INDEX($C11:$G15, 6 - _xlfn.SEQUENCE(5), _xlfn.SEQUENCE(1,5)), BU10="180 Rotation", INDEX($C11:$G15, 6 - _xlfn.SEQUENCE(5), 6 - _xlfn.SEQUENCE(1,5)), BU10="90 CW", INDEX($C11:$G15, 6 - _xlfn.SEQUENCE(1,5), _xlfn.SEQUENCE(5)), BU10="90 CCW", INDEX($C11:$G15, _xlfn.SEQUENCE(1,5), 6 - _xlfn.SEQUENCE(5)), BU10="Shift Up", IF(_xlfn.SEQUENCE(5)+1<=5, INDEX($C11:$G15, _xlfn.SEQUENCE(5)+1, _xlfn.SEQUENCE(1,5)), 0), BU10="Shift Down", IF(_xlfn.SEQUENCE(5)-1>=1, INDEX($C11:$G15, _xlfn.SEQUENCE(5)-1, _xlfn.SEQUENCE(1,5)), 0), BU10="Shift Left", IF(_xlfn.SEQUENCE(1,5)+1<=5, INDEX($C11:$G15, _xlfn.SEQUENCE(5), _xlfn.SEQUENCE(1,5)+1),0), BU10= "Shift Right", IF(_xlfn.SEQUENCE(1,5)-1>=1, INDEX($C11:$G15, _xlfn.SEQUENCE(5), _xlfn.SEQUENCE(1,5)-1), 0), BU10="Noise", _xlfn.MAP($C11:$G15 + (_xlfn.RANDARRAY(ROWS($C11:$G15), COLUMNS($C11:$G15)) - 0.5) * 0.4, _xlfn.LAMBDA(_xlpm.x, MAX(0, MIN(1, _xlpm.x)))))} -> 0.52525198 | BV11: 1 | BW11: 1 | BX11: 0.27029772 | BY11: 0.62339485
C12: 0.52525198 | D12: 1 | E12: 1 | F12: 0.27029772 | G12: 0.62339485 | J12: 0.36064882 | K12: 0.27631196 | L12: 1 | M12: 0.42164084 | N12: 0.41742635 | Q12: 0.62339485 | R12: 0.27029772 | S12: 1 | T12: 1 | U12: 0.52525198 | X12: 0 | Y12: 0.52525198 | Z12: 1 | AA12: 1 | AB12: 0.27029772 | AE12: 1 | AF12: 0.27631196 | AG12: 0.33592483 | AH12: 1 | AI12: 0.32578389 | AL12: 1 | AM12: 1 | AN12: 0.27029772 | AO12: 0.62339485 | AP12: 0 | AS12: 0.39514311 | AT12: 1 | AU12: 0.96269572 | AV12: 0.097624119 | AW12: 0.46604286 | AZ12: 0.41742635 | BA12: 0.42164084 | BB12: 1 | BC12: 0.27631196 | BD12: 0.36064882 | BG12: 0.49852125 | BH12: 0.32578389 | BI12: 1 | BJ12: 0.23722851 | BK12: 0.57956458 | BN12: 0.23722851 | BO12: 0.27029772 | BP12: 0.3775074 | BQ12: 0.42164084 | BR12: 1 | BU12: 0.29327062 | BV12: 0.33592483 | BW12: 1 | BX12: 0.3775074 | BY12: 0.44243688
C13: 0.29327062 | D13: 0.33592483 | E13: 1 | F13: 0.3775074 | G13: 0.44243688 | J13: 0.29327062 | K13: 0.33592483 | L13: 1 | M13: 0.3775074 | N13: 0.44243688 | Q13: 0.44243688 | R13: 0.3775074 | S13: 1 | T13: 0.33592483 | U13: 0.29327062 | X13: 0 | Y13: 0.29327062 | Z13: 0.33592483 | AA13: 1 | AB13: 0.3775074 | AE13: 1 | AF13: 1 | AG13: 1 | AH13: 1 | AI13: 1 | AL13: 0.33592483 | AM13: 1 | AN13: 0.3775074 | AO13: 0.44243688 | AP13: 0 | AS13: 0.20813915 | AT13: 0.42574423 | AU13: 1 | AV13: 0.40215104 | AW13: 0.29936562 | AZ13: 0.44243688 | BA13: 0.3775074 | BB13: 1 | BC13: 0.33592483 | BD13: 0.29327062 | BG13: 0.52525198 | BH13: 1 | BI13: 1 | BJ13: 0.27029772 | BK13: 0.62339485 | BN13: 1 | BO13: 1 | BP13: 1 | BQ13: 1 | BR13: 1 | BU13: 0.36064882 | BV13: 0.27631196 | BW13: 1 | BX13: 0.42164084 | BY13: 0.41742635
C14: 0.36064882 | D14: 0.27631196 | E14: 1 | F14: 0.42164084 | G14: 0.41742635 | J14: 0.52525198 | K14: 1 | L14: 1 | M14: 0.27029772 | N14: 0.62339485 | Q14: 0.41742635 | R14: 0.42164084 | S14: 1 | T14: 0.27631196 | U14: 0.36064882 | X14: 0 | Y14: 0.36064882 | Z14: 0.27631196 | AA14: 1 | AB14: 0.42164084 | AE14: 1 | AF14: 0.42164084 | AG14: 0.3775074 | AH14: 0.27029772 | AI14: 0.23722851 | AL14: 0.27631196 | AM14: 1 | AN14: 0.42164084 | AO14: 0.41742635 | AP14: 0 | AS14: 0.20677606 | AT14: 0.40033264 | AU14: 0.88690199 | AV14: 0.62078518 | AW14: 0.34919764 | AZ14: 0.62339485 | BA14: 0.27029772 | BB14: 1 | BC14: 1 | BD14: 0.52525198 | BG14: 0.29327062 | BH14: 0.33592483 | BI14: 1 | BJ14: 0.3775074 | BK14: 0.44243688 | BN14: 0.32578389 | BO14: 1 | BP14: 0.33592483 | BQ14: 0.27631196 | BR14: 1 | BU14: 0.33432835 | BV14: 1 | BW14: 1 | BX14: 1 | BY14: 0.18222316
C15: 0.33432835 | D15: 1 | E15: 1 | F15: 1 | G15: 0.18222316 | J15: 0.49852125 | K15: 0.32578389 | L15: 1 | M15: 0.23722851 | N15: 0.57956458 | Q15: 0.18222316 | R15: 1 | S15: 1 | T15: 1 | U15: 0.33432835 | X15: 0 | Y15: 0.33432835 | Z15: 1 | AA15: 1 | AB15: 1 | AE15: 0.18222316 | AF15: 0.41742635 | AG15: 0.44243688 | AH15: 0.62339485 | AI15: 0.57956458 | AL15: 1 | AM15: 1 | AN15: 1 | AO15: 0.18222316 | AP15: 0 | AS15: 0.16831779 | AT15: 1 | AU15: 1 | AV15: 0.93603055 | AW15: 0.067149824 | AZ15: 0.57956458 | BA15: 0.23722851 | BB15: 1 | BC15: 0.32578389 | BD15: 0.49852125 | BG15: 0.36064882 | BH15: 0.27631196 | BI15: 1 | BJ15: 0.42164084 | BK15: 0.41742635 | BN15: 0.49852125 | BO15: 0.52525198 | BP15: 0.29327062 | BQ15: 0.36064882 | BR15: 0.33432835 | BU15: 0 | BV15: 0 | BW15: 0 | BX15: 0 | BY15: 0
B17: 2 | C17: Original | J17: {=INDEX(Helper!$E$13:$E$22, OFFSET(Helper!$J$13,$B17,J$2))} -> Shift Left | Q17: {=INDEX(Helper!$E$13:$E$22, OFFSET(Helper!$J$13,$B17,Q$2))} -> Noise | X17: {=INDEX(Helper!$E$13:$E$22, OFFSET(Helper!$J$13,$B17,X$2))} -> Shift Up | AE17: {=INDEX(Helper!$E$13:$E$22, OFFSET(Helper!$J$13,$B17,AE$2))} -> Shift Right | AL17: {=INDEX(Helper!$E$13:$E$22, OFFSET(Helper!$J$13,$B17,AL$2))} -> Shift Down | AS17: {=INDEX(Helper!$E$13:$E$22, OFFSET(Helper!$J$13,$B17,AS$2))} -> 180 Rotation | AZ17: {=INDEX(Helper!$E$13:$E$22, OFFSET(Helper!$J$13,$B17,AZ$2))} -> 90 CCW | BG17: {=INDEX(Helper!$E$13:$E$22, OFFSET(Helper!$J$13,$B17,BG$2))} -> Vertical Flip | BN17: {=INDEX(Helper!$E$13:$E$22, OFFSET(Helper!$J$13,$B17,BN$2))} -> Horizontal Flip | BU17: {=INDEX(Helper!$E$13:$E$22, OFFSET(Helper!$J$13,$B17,BU$2))} -> 90 CW
C18: 0.28348784 | D18: 1 | E18: 1 | F18: 1 | G18: 0.23264272 | J18: {=_xlfn.IFS(J17="None", $C18:$G22*0, J17="Horizontal Flip", INDEX($C18:$G22, _xlfn.SEQUENCE(5), 6 - _xlfn.SEQUENCE(1,5)), J17="Vertical Flip", INDEX($C18:$G22, 6 - _xlfn.SEQUENCE(5), _xlfn.SEQUENCE(1,5)), J17="180 Rotation", INDEX($C18:$G22, 6 - _xlfn.SEQUENCE(5), 6 - _xlfn.SEQUENCE(1,5)), J17="90 CW", INDEX($C18:$G22, 6 - _xlfn.SEQUENCE(1,5), _xlfn.SEQUENCE(5)), J17="90 CCW", INDEX($C18:$G22, _xlfn.SEQUENCE(1,5), 6 - _xlfn.SEQUENCE(5)), J17="Shift Up", IF(_xlfn.SEQUENCE(5)+1<=5, INDEX($C18:$G22, _xlfn.SEQUENCE(5)+1, _xlfn.SEQUENCE(1,5)), 0), J17="Shift Down", IF(_xlfn.SEQUENCE(5)-1>=1, INDEX($C18:$G22, _xlfn.SEQUENCE(5)-1, _xlfn.SEQUENCE(1,5)), 0), J17="Shift Left", IF(_xlfn.SEQUENCE(1,5)+1<=5, INDEX($C18:$G22, _xlfn.SEQUENCE(5), _xlfn.SEQUENCE(1,5)+1),0), J17= "Shift Right", IF(_xlfn.SEQUENCE(1,5)-1>=1, INDEX($C18:$G22, _xlfn.SEQUENCE(5), _xlfn.SEQUENCE(1,5)-1), 0), J17="Noise", _xlfn.MAP($C18:$G22 + (_xlfn.RANDARRAY(ROWS($C18:$G22), COLUMNS($C18:$G22)) - 0.5) * 0.4, _xlfn.LAMBDA(_xlpm.x, MAX(0, MIN(1, _xlpm.x)))))} -> 1 | K18: 1 | L18: 1 | M18: 0.23264272 | N18: 0 | Q18: {=_xlfn.IFS(Q17="None", $C18:$G22*0, Q17="Horizontal Flip", INDEX($C18:$G22, _xlfn.SEQUENCE(5), 6 - _xlfn.SEQUENCE(1,5)), Q17="Vertical Flip", INDEX($C18:$G22, 6 - _xlfn.SEQUENCE(5), _xlfn.SEQUENCE(1,5)), Q17="180 Rotation", INDEX($C18:$G22, 6 - _xlfn.SEQUENCE(5), 6 - _xlfn.SEQUENCE(1,5)), Q17="90 CW", INDEX($C18:$G22, 6 - _xlfn.SEQUENCE(1,5), _xlfn.SEQUENCE(5)), Q17="90 CCW", INDEX($C18:$G22, _xlfn.SEQUENCE(1,5), 6 - _xlfn.SEQUENCE(5)), Q17="Shift Up", IF(_xlfn.SEQUENCE(5)+1<=5, INDEX($C18:$G22, _xlfn.SEQUENCE(5)+1, _xlfn.SEQUENCE(1,5)), 0), Q17="Shift Down", IF(_xlfn.SEQUENCE(5)-1>=1, INDEX($C18:$G22, _xlfn.SEQUENCE(5)-1, _xlfn.SEQUENCE(1,5)), 0), Q17="Shift Left", IF(_xlfn.SEQUENCE(1,5)+1<=5, INDEX($C18:$G22, _xlfn.SEQUENCE(5), _xlfn.SEQUENCE(1,5)+1),0), Q17= "Shift Right", IF(_xlfn.SEQUENCE(1,5)-1>=1, INDEX($C18:$G22, _xlfn.SEQUENCE(5), _xlfn.SEQUENCE(1,5)-1), 0), Q17="Noise", _xlfn.MAP($C18:$G22 + (_xlfn.RANDARRAY(ROWS($C18:$G22), COLUMNS($C18:$G22)) - 0.5) * 0.4, _xlfn.LAMBDA(_xlpm.x, MAX(0, MIN(1, _xlpm.x)))))} -> 0.11507927 | R18: 1 | S18: 1 | T18: 1 | U18: 0.11664924 | X18: {=_xlfn.IFS(X17="None", $C18:$G22*0, X17="Horizontal Flip", INDEX($C18:$G22, _xlfn.SEQUENCE(5), 6 - _xlfn.SEQUENCE(1,5)), X17="Vertical Flip", INDEX($C18:$G22, 6 - _xlfn.SEQUENCE(5), _xlfn.SEQUENCE(1,5)), X17="180 Rotation", INDEX($C18:$G22, 6 - _xlfn.SEQUENCE(5), 6 - _xlfn.SEQUENCE(1,5)), X17="90 CW", INDEX($C18:$G22, 6 - _xlfn.SEQUENCE(1,5), _xlfn.SEQUENCE(5)), X17="90 CCW", INDEX($C18:$G22, _xlfn.SEQUENCE(1,5), 6 - _xlfn.SEQUENCE(5)), X17="Shift Up", IF(_xlfn.SEQUENCE(5)+1<=5, INDEX($C18:$G22, _xlfn.SEQUENCE(5)+1, _xlfn.SEQUENCE(1,5)), 0), X17="Shift Down", IF(_xlfn.SEQUENCE(5)-1>=1, INDEX($C18:$G22, _xlfn.SEQUENCE(5)-1, _xlfn.SEQUENCE(1,5)), 0), X17="Shift Left", IF(_xlfn.SEQUENCE(1,5)+1<=5, INDEX($C18:$G22, _xlfn.SEQUENCE(5), _xlfn.SEQUENCE(1,5)+1),0), X17= "Shift Right", IF(_xlfn.SEQUENCE(1,5)-1>=1, INDEX($C18:$G22, _xlfn.SEQUENCE(5), _xlfn.SEQUENCE(1,5)-1), 0), X17="Noise", _xlfn.MAP($C18:$G22 + (_xlfn.RANDARRAY(ROWS($C18:$G22), COLUMNS($C18:$G22)) - 0.5) * 0.4, _xlfn.LAMBDA(_xlpm.x, MAX(0, MIN(1, _xlpm.x)))))} -> 0.46624032 | Y18: 0.62000165 | Z18: 0.34934612 | AA18: 1 | AB18: 0.55681088 | AE18: {=_xlfn.IFS(AE17="None", $C18:$G22*0, AE17="Horizontal Flip", INDEX($C18:$G22, _xlfn.SEQUENCE(5), 6 - _xlfn.SEQUENCE(1,5)), AE17="Vertical Flip", INDEX($C18:$G22, 6 - _xlfn.SEQUENCE(5), _xlfn.SEQUENCE(1,5)), AE17="180 Rotation", INDEX($C18:$G22, 6 - _xlfn.SEQUENCE(5), 6 - _xlfn.SEQUENCE(1,5)), AE17="90 CW", INDEX($C18:$G22, 6 - _xlfn.SEQUENCE(1,5), _xlfn.SEQUENCE(5)), AE17="90 CCW", INDEX($C18:$G22, _xlfn.SEQUENCE(1,5), 6 - _xlfn.SEQUENCE(5)), AE17="Shift Up", IF(_xlfn.SEQUENCE(5)+1<=5, INDEX($C18:$G22, _xlfn.SEQUENCE(5)+1, _xlfn.SEQUENCE(1,5)), 0), AE17="Shift Down", IF(_xlfn.SEQUENCE(5)-1>=1, INDEX($C18:$G22, _xlfn.SEQUENCE(5)-1, _xlfn.SEQUENCE(1,5)), 0), AE17="Shift Left", IF(_xlfn.SEQUENCE(1,5)+1<=5, INDEX($C18:$G22, _xlfn.SEQUENCE(5), _xlfn.SEQUENCE(1,5)+1),0), AE17= "Shift Right", IF(_xlfn.SEQUENCE(1,5)-1>=1, INDEX($C18:$G22, _xlfn.SEQUENCE(5), _xlfn.SEQUENCE(1,5)-1), 0), AE17="Noise", _xlfn.MAP($C18:$G22 + (_xlfn.RANDARRAY(ROWS($C18:$G22), COLUMNS($C18:$G22)) - 0.5) * 0.4, _xlfn.LAMBDA(_xlpm.x, MAX(0, MIN(1, _xlpm.x)))))} -> 0 | AF18: 0.28348784 | AG18: 1 | AH18: 1 | AI18: 1 | AL18: {=_xlfn.IFS(AL17="None", $C18:$G22*0, AL17="Horizontal Flip", INDEX($C18:$G22, _xlfn.SEQUENCE(5), 6 - _xlfn.SEQUENCE(1,5)), AL17="Vertical Flip", INDEX($C18:$G22, 6 - _xlfn.SEQUENCE(5), _xlfn.SEQUENCE(1,5)), AL17="180 Rotation", INDEX($C18:$G22, 6 - _xlfn.SEQUENCE(5), 6 - _xlfn.SEQUENCE(1,5)), AL17="90 CW", INDEX($C18:$G22, 6 - _xlfn.SEQUENCE(1,5), _xlfn.SEQUENCE(5)), AL17="90 CCW", INDEX($C18:$G22, _xlfn.SEQUENCE(1,5), 6 - _xlfn.SEQUENCE(5)), AL17="Shift Up", IF(_xlfn.SEQUENCE(5)+1<=5, INDEX($C18:$G22, _xlfn.SEQUENCE(5)+1, _xlfn.SEQUENCE(1,5)), 0), AL17="Shift Down", IF(_xlfn.SEQUENCE(5)-1>=1, INDEX($C18:$G22, _xlfn.SEQUENCE(5)-1, _xlfn.SEQUENCE(1,5)), 0), AL17="Shift Left", IF(_xlfn.SEQUENCE(1,5)+1<=5, INDEX($C18:$G22, _xlfn.SEQUENCE(5), _xlfn.SEQUENCE(1,5)+1),0), AL17= "Shift Right", IF(_xlfn.SEQUENCE(1,5)-1>=1, INDEX($C18:$G22, _xlfn.SEQUENCE(5), _xlfn.SEQUENCE(1,5)-1), 0), AL17="Noise", _xlfn.MAP($C18:$G22 + (_xlfn.RANDARRAY(ROWS($C18:$G22), COLUMNS($C18:$G22)) - 0.5) * 0.4, _xlfn.LAMBDA(_xlpm.x, MAX(0, MIN(1, _xlpm.x)))))} -> 0 | AM18: 0 | AN18: 0 | AO18: 0 | AP18: 0 | AS18: {=_xlfn.IFS(AS17="None", $C18:$G22*0, AS17="Horizontal Flip", INDEX($C18:$G22, _xlfn.SEQUENCE(5), 6 - _xlfn.SEQUENCE(1,5)), AS17="Vertical Flip", INDEX($C18:$G22, 6 - _xlfn.SEQUENCE(5), _xlfn.SEQUENCE(1,5)), AS17="180 Rotation", INDEX($C18:$G22, 6 - _xlfn.SEQUENCE(5), 6 - _xlfn.SEQUENCE(1,5)), AS17="90 CW", INDEX($C18:$G22, 6 - _xlfn.SEQUENCE(1,5), _xlfn.SEQUENCE(5)), AS17="90 CCW", INDEX($C18:$G22, _xlfn.SEQUENCE(1,5), 6 - _xlfn.SEQUENCE(5)), AS17="Shift Up", IF(_xlfn.SEQUENCE(5)+1<=5, INDEX($C18:$G22, _xlfn.SEQUENCE(5)+1, _xlfn.SEQUENCE(1,5)), 0), AS17="Shift Down", IF(_xlfn.SEQUENCE(5)-1>=1, INDEX($C18:$G22, _xlfn.SEQUENCE(5)-1, _xlfn.SEQUENCE(1,5)), 0), AS17="Shift Left", IF(_xlfn.SEQUENCE(1,5)+1<=5, INDEX($C18:$G22, _xlfn.SEQUENCE(5), _xlfn.SEQUENCE(1,5)+1),0), AS17= "Shift Right", IF(_xlfn.SEQUENCE(1,5)-1>=1, INDEX($C18:$G22, _xlfn.SEQUENCE(5), _xlfn.SEQUENCE(1,5)-1), 0), AS17="Noise", _xlfn.MAP($C18:$G22 + (_xlfn.RANDARRAY(ROWS($C18:$G22), COLUMNS($C18:$G22)) - 0.5) * 0.4, _xlfn.LAMBDA(_xlpm.x, MAX(0, MIN(1, _xlpm.x)))))} -> 0.29482848 | AT18: 1 | AU18: 1 | AV18: 1 | AW18: 0.61985861 | AZ18: {=_xlfn.IFS(AZ17="None", $C18:$G22*0, AZ17="Horizontal Flip", INDEX($C18:$G22, _xlfn.SEQUENCE(5), 6 - _xlfn.SEQUENCE(1,5)), AZ17="Vertical Flip", INDEX($C18:$G22, 6 - _xlfn.SEQUENCE(5), _xlfn.SEQUENCE(1,5)), AZ17="180 Rotation", INDEX($C18:$G22, 6 - _xlfn.SEQUENCE(5), 6 - _xlfn.SEQUENCE(1,5)), AZ17="90 CW", INDEX($C18:$G22, 6 - _xlfn.SEQUENCE(1,5), _xlfn.SEQUENCE(5)), AZ17="90 CCW", INDEX($C18:$G22, _xlfn.SEQUENCE(1,5), 6 - _xlfn.SEQUENCE(5)), AZ17="Shift Up", IF(_xlfn.SEQUENCE(5)+1<=5, INDEX($C18:$G22, _xlfn.SEQUENCE(5)+1, _xlfn.SEQUENCE(1,5)), 0), AZ17="Shift Down", IF(_xlfn.SEQUENCE(5)-1>=1, INDEX($C18:$G22, _xlfn.SEQUENCE(5)-1, _xlfn.SEQUENCE(1,5)), 0), AZ17="Shift Left", IF(_xlfn.SEQUENCE(1,5)+1<=5, INDEX($C18:$G22, _xlfn.SEQUENCE(5), _xlfn.SEQUENCE(1,5)+1),0), AZ17= "Shift Right", IF(_xlfn.SEQUENCE(1,5)-1>=1, INDEX($C18:$G22, _xlfn.SEQUENCE(5), _xlfn.SEQUENCE(1,5)-1), 0), AZ17="Noise", _xlfn.MAP($C18:$G22 + (_xlfn.RANDARRAY(ROWS($C18:$G22), COLUMNS($C18:$G22)) - 0.5) * 0.4, _xlfn.LAMBDA(_xlpm.x, MAX(0, MIN(1, _xlpm.x)))))} -> 0.23264272 | BA18: 0.55681088 | BB18: 0.31557817 | BC18: 0.23950235 | BD18: 0.29482848 | BG18: {=_xlfn.IFS(BG17="None", $C18:$G22*0, BG17="Horizontal Flip", INDEX($C18:$G22, _xlfn.SEQUENCE(5), 6 - _xlfn.SEQUENCE(1,5)), BG17="Vertical Flip", INDEX($C18:$G22, 6 - _xlfn.SEQUENCE(5), _xlfn.SEQUENCE(1,5)), BG17="180 Rotation", INDEX($C18:$G22, 6 - _xlfn.SEQUENCE(5), 6 - _xlfn.SEQUENCE(1,5)), BG17="90 CW", INDEX($C18:$G22, 6 - _xlfn.SEQUENCE(1,5), _xlfn.SEQUENCE(5)), BG17="90 CCW", INDEX($C18:$G22, _xlfn.SEQUENCE(1,5), 6 - _xlfn.SEQUENCE(5)), BG17="Shift Up", IF(_xlfn.SEQUENCE(5)+1<=5, INDEX($C18:$G22, _xlfn.SEQUENCE(5)+1, _xlfn.SEQUENCE(1,5)), 0), BG17="Shift Down", IF(_xlfn.SEQUENCE(5)-1>=1, INDEX($C18:$G22, _xlfn.SEQUENCE(5)-1, _xlfn.SEQUENCE(1,5)), 0), BG17="Shift Left", IF(_xlfn.SEQUENCE(1,5)+1<=5, INDEX($C18:$G22, _xlfn.SEQUENCE(5), _xlfn.SEQUENCE(1,5)+1),0), BG17= "Shift Right", IF(_xlfn.SEQUENCE(1,5)-1>=1, INDEX($C18:$G22, _xlfn.SEQUENCE(5), _xlfn.SEQUENCE(1,5)-1), 0), BG17="Noise", _xlfn.MAP($C18:$G22 + (_xlfn.RANDARRAY(ROWS($C18:$G22), COLUMNS($C18:$G22)) - 0.5) * 0.4, _xlfn.LAMBDA(_xlpm.x, MAX(0, MIN(1, _xlpm.x)))))} -> 0.61985861 | BH18: 1 | BI18: 1 | BJ18: 1 | BK18: 0.29482848 | BN18: {=_xlfn.IFS(BN17="None", $C18:$G22*0, BN17="Horizontal Flip", INDEX($C18:$G22, _xlfn.SEQUENCE(5), 6 - _xlfn.SEQUENCE(1,5)), BN17="Vertical Flip", INDEX($C18:$G22, 6 - _xlfn.SEQUENCE(5), _xlfn.SEQUENCE(1,5)), BN17="180 Rotation", INDEX($C18:$G22, 6 - _xlfn.SEQUENCE(5), 6 - _xlfn.SEQUENCE(1,5)), BN17="90 CW", INDEX($C18:$G22, 6 - _xlfn.SEQUENCE(1,5), _xlfn.SEQUENCE(5)), BN17="90 CCW", INDEX($C18:$G22, _xlfn.SEQUENCE(1,5), 6 - _xlfn.SEQUENCE(5)), BN17="Shift Up", IF(_xlfn.SEQUENCE(5)+1<=5, INDEX($C18:$G22, _xlfn.SEQUENCE(5)+1, _xlfn.SEQUENCE(1,5)), 0), BN17="Shift Down", IF(_xlfn.SEQUENCE(5)-1>=1, INDEX($C18:$G22, _xlfn.SEQUENCE(5)-1, _xlfn.SEQUENCE(1,5)), 0), BN17="Shift Left", IF(_xlfn.SEQUENCE(1,5)+1<=5, INDEX($C18:$G22, _xlfn.SEQUENCE(5), _xlfn.SEQUENCE(1,5)+1),0), BN17= "Shift Right", IF(_xlfn.SEQUENCE(1,5)-1>=1, INDEX($C18:$G22, _xlfn.SEQUENCE(5), _xlfn.SEQUENCE(1,5)-1), 0), BN17="Noise", _xlfn.MAP($C18:$G22 + (_xlfn.RANDARRAY(ROWS($C18:$G22), COLUMNS($C18:$G22)) - 0.5) * 0.4, _xlfn.LAMBDA(_xlpm.x, MAX(0, MIN(1, _xlpm.x)))))} -> 0.23264272 | BO18: 1 | BP18: 1 | BQ18: 1 | BR18: 0.28348784 | BU18: {=_xlfn.IFS(BU17="None", $C18:$G22*0, BU17="Horizontal Flip", INDEX($C18:$G22, _xlfn.SEQUENCE(5), 6 - _xlfn.SEQUENCE(1,5)), BU17="Vertical Flip", INDEX($C18:$G22, 6 - _xlfn.SEQUENCE(5), _xlfn.SEQUENCE(1,5)), BU17="180 Rotation", INDEX($C18:$G22, 6 - _xlfn.SEQUENCE(5), 6 - _xlfn.SEQUENCE(1,5)), BU17="90 CW", INDEX($C18:$G22, 6 - _xlfn.SEQUENCE(1,5), _xlfn.SEQUENCE(5)), BU17="90 CCW", INDEX($C18:$G22, _xlfn.SEQUENCE(1,5), 6 - _xlfn.SEQUENCE(5)), BU17="Shift Up", IF(_xlfn.SEQUENCE(5)+1<=5, INDEX($C18:$G22, _xlfn.SEQUENCE(5)+1, _xlfn.SEQUENCE(1,5)), 0), BU17="Shift Down", IF(_xlfn.SEQUENCE(5)-1>=1, INDEX($C18:$G22, _xlfn.SEQUENCE(5)-1, _xlfn.SEQUENCE(1,5)), 0), BU17="Shift Left", IF(_xlfn.SEQUENCE(1,5)+1<=5, INDEX($C18:$G22, _xlfn.SEQUENCE(5), _xlfn.SEQUENCE(1,5)+1),0), BU17= "Shift Right", IF(_xlfn.SEQUENCE(1,5)-1>=1, INDEX($C18:$G22, _xlfn.SEQUENCE(5), _xlfn.SEQUENCE(1,5)-1), 0), BU17="Noise", _xlfn.MAP($C18:$G22 + (_xlfn.RANDARRAY(ROWS($C18:$G22), COLUMNS($C18:$G22)) - 0.5) * 0.4, _xlfn.LAMBDA(_xlpm.x, MAX(0, MIN(1, _xlpm.x)))))} -> 0.61985861 | BV18: 0.19748848 | BW18: 0.1646772 | BX18: 0.46624032 | BY18: 0.28348784
C19: 0.46624032 | D19: 0.62000165 | E19: 0.34934612 | F19: 1 | G19: 0.55681088 | J19: 0.62000165 | K19: 0.34934612 | L19: 1 | M19: 0.55681088 | N19: 0 | Q19: 0.46006605 | R19: 0.77970095 | S19: 0.47328509 | T19: 0.83291812 | U19: 0.56336185 | X19: 0.1646772 | Y19: 1 | Z19: 1 | AA19: 1 | AB19: 0.31557817 | AE19: 0 | AF19: 0.46624032 | AG19: 0.62000165 | AH19: 0.34934612 | AI19: 1 | AL19: 0.28348784 | AM19: 1 | AN19: 1 | AO19: 1 | AP19: 0.23264272 | AS19: 0.23950235 | AT19: 0.19801098 | AU19: 0.28987371 | AV19: 1 | AW19: 0.19748848 | AZ19: 1 | BA19: 1 | BB19: 1 | BC19: 0.19801098 | BD19: 1 | BG19: 0.19748848 | BH19: 1 | BI19: 0.28987371 | BJ19: 0.19801098 | BK19: 0.23950235 | BN19: 0.55681088 | BO19: 1 | BP19: 0.34934612 | BQ19: 0.62000165 | BR19: 0.46624032 | BU19: 1 | BV19: 1 | BW19: 1 | BX19: 0.62000165 | BY19: 1
C20: 0.1646772 | D20: 1 | E20: 1 | F20: 1 | G20: 0.31557817 | J20: 1 | K20: 1 | L20: 1 | M20: 0.31557817 | N20: 0 | Q20: 0.31405441 | R20: 1 | S20: 1 | T20: 0.80491225 | U20: 0.44626309 | X20: 0.19748848 | Y20: 1 | Z20: 0.28987371 | AA20: 0.19801098 | AB20: 0.23950235 | AE20: 0 | AF20: 0.1646772 | AG20: 1 | AH20: 1 | AI20: 1 | AL20: 0.46624032 | AM20: 0.62000165 | AN20: 0.34934612 | AO20: 1 | AP20: 0.55681088 | AS20: 0.31557817 | AT20: 1 | AU20: 1 | AV20: 1 | AW20: 0.1646772 | AZ20: 1 | BA20: 0.34934612 | BB20: 1 | BC20: 0.28987371 | BD20: 1 | BG20: 0.1646772 | BH20: 1 | BI20: 1 | BJ20: 1 | BK20: 0.31557817 | BN20: 0.31557817 | BO20: 1 | BP20: 1 | BQ20: 1 | BR20: 0.1646772 | BU20: 1 | BV20: 0.28987371 | BW20: 1 | BX20: 0.34934612 | BY20: 1
C21: 0.19748848 | D21: 1 | E21: 0.28987371 | F21: 0.19801098 | G21: 0.23950235 | J21: 1 | K21: 0.28987371 | L21: 0.19801098 | M21: 0.23950235 | N21: 0 | Q21: 0.38894204 | R21: 1 | S21: 0.34658071 | T21: 0.19830158 | U21: 0.043887983 | X21: 0.61985861 | Y21: 1 | Z21: 1 | AA21: 1 | AB21: 0.29482848 | AE21: 0 | AF21: 0.19748848 | AG21: 1 | AH21: 0.28987371 | AI21: 0.19801098 | AL21: 0.1646772 | AM21: 1 | AN21: 1 | AO21: 1 | AP21: 0.31557817 | AS21: 0.55681088 | AT21: 1 | AU21: 0.34934612 | AV21: 0.62000165 | AW21: 0.46624032 | AZ21: 1 | BA21: 0.62000165 | BB21: 1 | BC21: 1 | BD21: 1 | BG21: 0.46624032 | BH21: 0.62000165 | BI21: 0.34934612 | BJ21: 1 | BK21: 0.55681088 | BN21: 0.23950235 | BO21: 0.19801098 | BP21: 0.28987371 | BQ21: 1 | BR21: 0.19748848 | BU21: 1 | BV21: 0.19801098 | BW21: 1 | BX21: 1 | BY21: 1
C22: 0.61985861 | D22: 1 | E22: 1 | F22: 1 | G22: 0.29482848 | J22: 1 | K22: 1 | L22: 1 | M22: 0.29482848 | N22: 0 | Q22: 0.76326701 | R22: 0.93536606 | S22: 0.97316374 | T22: 1 | U22: 0.42673106 | X22: 0 | Y22: 0 | Z22: 0 | AA22: 0 | AB22: 0 | AE22: 0 | AF22: 0.61985861 | AG22: 1 | AH22: 1 | AI22: 1 | AL22: 0.19748848 | AM22: 1 | AN22: 0.28987371 | AO22: 0.19801098 | AP22: 0.23950235 | AS22: 0.23264272 | AT22: 1 | AU22: 1 | AV22: 1 | AW22: 0.28348784 | AZ22: 0.28348784 | BA22: 0.46624032 | BB22: 0.1646772 | BC22: 0.19748848 | BD22: 0.61985861 | BG22: 0.28348784 | BH22: 1 | BI22: 1 | BJ22: 1 | BK22: 0.23264272 | BN22: 0.29482848 | BO22: 1 | BP22: 1 | BQ22: 1 | BR22: 0.61985861 | BU22: 0.29482848 | BV22: 0.23950235 | BW22: 0.31557817 | BX22: 0.55681088 | BY22: 0.23264272
B24: 3 | C24: Original | J24: {=INDEX(Helper!$E$13:$E$22, OFFSET(Helper!$J$13,$B24,J$2))} -> Shift Up | Q24: {=INDEX(Helper!$E$13:$E$22, OFFSET(Helper!$J$13,$B24,Q$2))} -> Vertical Flip | X24: {=INDEX(Helper!$E$13:$E$22, OFFSET(Helper!$J$13,$B24,X$2))} -> 180 Rotation | AE24: {=INDEX(Helper!$E$13:$E$22, OFFSET(Helper!$J$13,$B24,AE$2))} -> Horizontal Flip | AL24: {=INDEX(Helper!$E$13:$E$22, OFFSET(Helper!$J$13,$B24,AL$2))} -> 90 CCW | AS24: {=INDEX(Helper!$E$13:$E$22, OFFSET(Helper!$J$13,$B24,AS$2))} -> Shift Down | AZ24: {=INDEX(Helper!$E$13:$E$22, OFFSET(Helper!$J$13,$B24,AZ$2))} -> Shift Right | BG24: {=INDEX(Helper!$E$13:$E$22, OFFSET(Helper!$J$13,$B24,BG$2))} -> Shift Left | BN24: {=INDEX(Helper!$E$13:$E$22, OFFSET(Helper!$J$13,$B24,BN$2))} -> Noise | BU24: {=INDEX(Helper!$E$13:$E$22, OFFSET(Helper!$J$13,$B24,BU$2))} -> 90 CW
C25: 0.45498379 | D25: 1 | E25: 1 | F25: 1 | G25: 0.2291328 | J25: {=_xlfn.IFS(J24="None", $C25:$G29*0, J24="Horizontal Flip", INDEX($C25:$G29, _xlfn.SEQUENCE(5), 6 - _xlfn.SEQUENCE(1,5)), J24="Vertical Flip", INDEX($C25:$G29, 6 - _xlfn.SEQUENCE(5), _xlfn.SEQUENCE(1,5)), J24="180 Rotation", INDEX($C25:$G29, 6 - _xlfn.SEQUENCE(5), 6 - _xlfn.SEQUENCE(1,5)), J24="90 CW", INDEX($C25:$G29, 6 - _xlfn.SEQUENCE(1,5), _xlfn.SEQUENCE(5)), J24="90 CCW", INDEX($C25:$G29, _xlfn.SEQUENCE(1,5), 6 - _xlfn.SEQUENCE(5)), J24="Shift Up", IF(_xlfn.SEQUENCE(5)+1<=5, INDEX($C25:$G29, _xlfn.SEQUENCE(5)+1, _xlfn.SEQUENCE(1,5)), 0), J24="Shift Down", IF(_xlfn.SEQUENCE(5)-1>=1, INDEX($C25:$G29, _xlfn.SEQUENCE(5)-1, _xlfn.SEQUENCE(1,5)), 0), J24="Shift Left", IF(_xlfn.SEQUENCE(1,5)+1<=5, INDEX($C25:$G29, _xlfn.SEQUENCE(5), _xlfn.SEQUENCE(1,5)+1),0), J24= "Shift Right", IF(_xlfn.SEQUENCE(1,5)-1>=1, INDEX($C25:$G29, _xlfn.SEQUENCE(5), _xlfn.SEQUENCE(1,5)-1), 0), J24="Noise", _xlfn.MAP($C25:$G29 + (_xlfn.RANDARRAY(ROWS($C25:$G29), COLUMNS($C25:$G29)) - 0.5) * 0.4, _xlfn.LAMBDA(_xlpm.x, MAX(0, MIN(1, _xlpm.x)))))} -> 0.5769979 | K25: 0.38322233 | L25: 0.15720976 | M25: 1 | N25: 0.30909224 | Q25: {=_xlfn.IFS(Q24="None", $C25:$G29*0, Q24="Horizontal Flip", INDEX($C25:$G29, _xlfn.SEQUENCE(5), 6 - _xlfn.SEQUENCE(1,5)), Q24="Vertical Flip", INDEX($C25:$G29, 6 - _xlfn.SEQUENCE(5), _xlfn.SEQUENCE(1,5)), Q24="180 Rotation", INDEX($C25:$G29, 6 - _xlfn.SEQUENCE(5), 6 - _xlfn.SEQUENCE(1,5)), Q24="90 CW", INDEX($C25:$G29, 6 - _xlfn.SEQUENCE(1,5), _xlfn.SEQUENCE(5)), Q24="90 CCW", INDEX($C25:$G29, _xlfn.SEQUENCE(1,5), 6 - _xlfn.SEQUENCE(5)), Q24="Shift Up", IF(_xlfn.SEQUENCE(5)+1<=5, INDEX($C25:$G29, _xlfn.SEQUENCE(5)+1, _xlfn.SEQUENCE(1,5)), 0), Q24="Shift Down", IF(_xlfn.SEQUENCE(5)-1>=1, INDEX($C25:$G29, _xlfn.SEQUENCE(5)-1, _xlfn.SEQUENCE(1,5)), 0), Q24="Shift Left", IF(_xlfn.SEQUENCE(1,5)+1<=5, INDEX($C25:$G29, _xlfn.SEQUENCE(5), _xlfn.SEQUENCE(1,5)+1),0), Q24= "Shift Right", IF(_xlfn.SEQUENCE(1,5)-1>=1, INDEX($C25:$G29, _xlfn.SEQUENCE(5), _xlfn.SEQUENCE(1,5)-1), 0), Q24="Noise", _xlfn.MAP($C25:$G29 + (_xlfn.RANDARRAY(ROWS($C25:$G29), COLUMNS($C25:$G29)) - 0.5) * 0.4, _xlfn.LAMBDA(_xlpm.x, MAX(0, MIN(1, _xlpm.x)))))} -> 0.47361589 | R25: 1 | S25: 1 | T25: 1 | U25: 0.31808908 | X25: {=_xlfn.IFS(X24="None", $C25:$G29*0, X24="Horizontal Flip", INDEX($C25:$G29, _xlfn.SEQUENCE(5), 6 - _xlfn.SEQUENCE(1,5)), X24="Vertical Flip", INDEX($C25:$G29, 6 - _xlfn.SEQUENCE(5), _xlfn.SEQUENCE(1,5)), X24="180 Rotation", INDEX($C25:$G29, 6 - _xlfn.SEQUENCE(5), 6 - _xlfn.SEQUENCE(1,5)), X24="90 CW", INDEX($C25:$G29, 6 - _xlfn.SEQUENCE(1,5), _xlfn.SEQUENCE(5)), X24="90 CCW", INDEX($C25:$G29, _xlfn.SEQUENCE(1,5), 6 - _xlfn.SEQUENCE(5)), X24="Shift Up", IF(_xlfn.SEQUENCE(5)+1<=5, INDEX($C25:$G29, _xlfn.SEQUENCE(5)+1, _xlfn.SEQUENCE(1,5)), 0), X24="Shift Down", IF(_xlfn.SEQUENCE(5)-1>=1, INDEX($C25:$G29, _xlfn.SEQUENCE(5)-1, _xlfn.SEQUENCE(1,5)), 0), X24="Shift Left", IF(_xlfn.SEQUENCE(1,5)+1<=5, INDEX($C25:$G29, _xlfn.SEQUENCE(5), _xlfn.SEQUENCE(1,5)+1),0), X24= "Shift Right", IF(_xlfn.SEQUENCE(1,5)-1>=1, INDEX($C25:$G29, _xlfn.SEQUENCE(5), _xlfn.SEQUENCE(1,5)-1), 0), X24="Noise", _xlfn.MAP($C25:$G29 + (_xlfn.RANDARRAY(ROWS($C25:$G29), COLUMNS($C25:$G29)) - 0.5) * 0.4, _xlfn.LAMBDA(_xlpm.x, MAX(0, MIN(1, _xlpm.x)))))} -> 0.31808908 | Y25: 1 | Z25: 1 | AA25: 1 | AB25: 0.47361589 | AE25: {=_xlfn.IFS(AE24="None", $C25:$G29*0, AE24="Horizontal Flip", INDEX($C25:$G29, _xlfn.SEQUENCE(5), 6 - _xlfn.SEQUENCE(1,5)), AE24="Vertical Flip", INDEX($C25:$G29, 6 - _xlfn.SEQUENCE(5), _xlfn.SEQUENCE(1,5)), AE24="180 Rotation", INDEX($C25:$G29, 6 - _xlfn.SEQUENCE(5), 6 - _xlfn.SEQUENCE(1,5)), AE24="90 CW", INDEX($C25:$G29, 6 - _xlfn.SEQUENCE(1,5), _xlfn.SEQUENCE(5)), AE24="90 CCW", INDEX($C25:$G29, _xlfn.SEQUENCE(1,5), 6 - _xlfn.SEQUENCE(5)), AE24="Shift Up", IF(_xlfn.SEQUENCE(5)+1<=5, INDEX($C25:$G29, _xlfn.SEQUENCE(5)+1, _xlfn.SEQUENCE(1,5)), 0), AE24="Shift Down", IF(_xlfn.SEQUENCE(5)-1>=1, INDEX($C25:$G29, _xlfn.SEQUENCE(5)-1, _xlfn.SEQUENCE(1,5)), 0), AE24="Shift Left", IF(_xlfn.SEQUENCE(1,5)+1<=5, INDEX($C25:$G29, _xlfn.SEQUENCE(5), _xlfn.SEQUENCE(1,5)+1),0), AE24= "Shift Right", IF(_xlfn.SEQUENCE(1,5)-1>=1, INDEX($C25:$G29, _xlfn.SEQUENCE(5), _xlfn.SEQUENCE(1,5)-1), 0), AE24="Noise", _xlfn.MAP($C25:$G29 + (_xlfn.RANDARRAY(ROWS($C25:$G29), COLUMNS($C25:$G29)) - 0.5) * 0.4, _xlfn.LAMBDA(_xlpm.x, MAX(0, MIN(1, _xlpm.x)))))} -> 0.2291328 | AF25: 1 | AG25: 1 | AH25: 1 | AI25: 0.45498379 | AL25: {=_xlfn.IFS(AL24="None", $C25:$G29*0, AL24="Horizontal Flip", INDEX($C25:$G29, _xlfn.SEQUENCE(5), 6 - _xlfn.SEQUENCE(1,5)), AL24="Vertical Flip", INDEX($C25:$G29, 6 - _xlfn.SEQUENCE(5), _xlfn.SEQUENCE(1,5)), AL24="180 Rotation", INDEX($C25:$G29, 6 - _xlfn.SEQUENCE(5), 6 - _xlfn.SEQUENCE(1,5)), AL24="90 CW", INDEX($C25:$G29, 6 - _xlfn.SEQUENCE(1,5), _xlfn.SEQUENCE(5)), AL24="90 CCW", INDEX($C25:$G29, _xlfn.SEQUENCE(1,5), 6 - _xlfn.SEQUENCE(5)), AL24="Shift Up", IF(_xlfn.SEQUENCE(5)+1<=5, INDEX($C25:$G29, _xlfn.SEQUENCE(5)+1, _xlfn.SEQUENCE(1,5)), 0), AL24="Shift Down", IF(_xlfn.SEQUENCE(5)-1>=1, INDEX($C25:$G29, _xlfn.SEQUENCE(5)-1, _xlfn.SEQUENCE(1,5)), 0), AL24="Shift Left", IF(_xlfn.SEQUENCE(1,5)+1<=5, INDEX($C25:$G29, _xlfn.SEQUENCE(5), _xlfn.SEQUENCE(1,5)+1),0), AL24= "Shift Right", IF(_xlfn.SEQUENCE(1,5)-1>=1, INDEX($C25:$G29, _xlfn.SEQUENCE(5), _xlfn.SEQUENCE(1,5)-1), 0), AL24="Noise", _xlfn.MAP($C25:$G29 + (_xlfn.RANDARRAY(ROWS($C25:$G29), COLUMNS($C25:$G29)) - 0.5) * 0.4, _xlfn.LAMBDA(_xlpm.x, MAX(0, MIN(1, _xlpm.x)))))} -> 0.2291328 | AM25: 0.30909224 | AN25: 0.45743299 | AO25: 0.57160394 | AP25: 0.31808908 | AS25: {=_xlfn.IFS(AS24="None", $C25:$G29*0, AS24="Horizontal Flip", INDEX($C25:$G29, _xlfn.SEQUENCE(5), 6 - _xlfn.SEQUENCE(1,5)), AS24="Vertical Flip", INDEX($C25:$G29, 6 - _xlfn.SEQUENCE(5), _xlfn.SEQUENCE(1,5)), AS24="180 Rotation", INDEX($C25:$G29, 6 - _xlfn.SEQUENCE(5), 6 - _xlfn.SEQUENCE(1,5)), AS24="90 CW", INDEX($C25:$G29, 6 - _xlfn.SEQUENCE(1,5), _xlfn.SEQUENCE(5)), AS24="90 CCW", INDEX($C25:$G29, _xlfn.SEQUENCE(1,5), 6 - _xlfn.SEQUENCE(5)), AS24="Shift Up", IF(_xlfn.SEQUENCE(5)+1<=5, INDEX($C25:$G29, _xlfn.SEQUENCE(5)+1, _xlfn.SEQUENCE(1,5)), 0), AS24="Shift Down", IF(_xlfn.SEQUENCE(5)-1>=1, INDEX($C25:$G29, _xlfn.SEQUENCE(5)-1, _xlfn.SEQUENCE(1,5)), 0), AS24="Shift Left", IF(_xlfn.SEQUENCE(1,5)+1<=5, INDEX($C25:$G29, _xlfn.SEQUENCE(5), _xlfn.SEQUENCE(1,5)+1),0), AS24= "Shift Right", IF(_xlfn.SEQUENCE(1,5)-1>=1, INDEX($C25:$G29, _xlfn.SEQUENCE(5), _xlfn.SEQUENCE(1,5)-1), 0), AS24="Noise", _xlfn.MAP($C25:$G29 + (_xlfn.RANDARRAY(ROWS($C25:$G29), COLUMNS($C25:$G29)) - 0.5) * 0.4, _xlfn.LAMBDA(_xlpm.x, MAX(0, MIN(1, _xlpm.x)))))} -> 0 | AT25: 0 | AU25: 0 | AV25: 0 | AW25: 0 | AZ25: {=_xlfn.IFS(AZ24="None", $C25:$G29*0, AZ24="Horizontal Flip", INDEX($C25:$G29, _xlfn.SEQUENCE(5), 6 - _xlfn.SEQUENCE(1,5)), AZ24="Vertical Flip", INDEX($C25:$G29, 6 - _xlfn.SEQUENCE(5), _xlfn.SEQUENCE(1,5)), AZ24="180 Rotation", INDEX($C25:$G29, 6 - _xlfn.SEQUENCE(5), 6 - _xlfn.SEQUENCE(1,5)), AZ24="90 CW", INDEX($C25:$G29, 6 - _xlfn.SEQUENCE(1,5), _xlfn.SEQUENCE(5)), AZ24="90 CCW", INDEX($C25:$G29, _xlfn.SEQUENCE(1,5), 6 - _xlfn.SEQUENCE(5)), AZ24="Shift Up", IF(_xlfn.SEQUENCE(5)+1<=5, INDEX($C25:$G29, _xlfn.SEQUENCE(5)+1, _xlfn.SEQUENCE(1,5)), 0), AZ24="Shift Down", IF(_xlfn.SEQUENCE(5)-1>=1, INDEX($C25:$G29, _xlfn.SEQUENCE(5)-1, _xlfn.SEQUENCE(1,5)), 0), AZ24="Shift Left", IF(_xlfn.SEQUENCE(1,5)+1<=5, INDEX($C25:$G29, _xlfn.SEQUENCE(5), _xlfn.SEQUENCE(1,5)+1),0), AZ24= "Shift Right", IF(_xlfn.SEQUENCE(1,5)-1>=1, INDEX($C25:$G29, _xlfn.SEQUENCE(5), _xlfn.SEQUENCE(1,5)-1), 0), AZ24="Noise", _xlfn.MAP($C25:$G29 + (_xlfn.RANDARRAY(ROWS($C25:$G29), COLUMNS($C25:$G29)) - 0.5) * 0.4, _xlfn.LAMBDA(_xlpm.x, MAX(0, MIN(1, _xlpm.x)))))} -> 0 | BA25: 0.45498379 | BB25: 1 | BC25: 1 | BD25: 1 | BG25: {=_xlfn.IFS(BG24="None", $C25:$G29*0, BG24="Horizontal Flip", INDEX($C25:$G29, _xlfn.SEQUENCE(5), 6 - _xlfn.SEQUENCE(1,5)), BG24="Vertical Flip", INDEX($C25:$G29, 6 - _xlfn.SEQUENCE(5), _xlfn.SEQUENCE(1,5)), BG24="180 Rotation", INDEX($C25:$G29, 6 - _xlfn.SEQUENCE(5), 6 - _xlfn.SEQUENCE(1,5)), BG24="90 CW", INDEX($C25:$G29, 6 - _xlfn.SEQUENCE(1,5), _xlfn.SEQUENCE(5)), BG24="90 CCW", INDEX($C25:$G29, _xlfn.SEQUENCE(1,5), 6 - _xlfn.SEQUENCE(5)), BG24="Shift Up", IF(_xlfn.SEQUENCE(5)+1<=5, INDEX($C25:$G29, _xlfn.SEQUENCE(5)+1, _xlfn.SEQUENCE(1,5)), 0), BG24="Shift Down", IF(_xlfn.SEQUENCE(5)-1>=1, INDEX($C25:$G29, _xlfn.SEQUENCE(5)-1, _xlfn.SEQUENCE(1,5)), 0), BG24="Shift Left", IF(_xlfn.SEQUENCE(1,5)+1<=5, INDEX($C25:$G29, _xlfn.SEQUENCE(5), _xlfn.SEQUENCE(1,5)+1),0), BG24= "Shift Right", IF(_xlfn.SEQUENCE(1,5)-1>=1, INDEX($C25:$G29, _xlfn.SEQUENCE(5), _xlfn.SEQUENCE(1,5)-1), 0), BG24="Noise", _xlfn.MAP($C25:$G29 + (_xlfn.RANDARRAY(ROWS($C25:$G29), COLUMNS($C25:$G29)) - 0.5) * 0.4, _xlfn.LAMBDA(_xlpm.x, MAX(0, MIN(1, _xlpm.x)))))} -> 1 | BH25: 1 | BI25: 1 | BJ25: 0.2291328 | BK25: 0 | BN25: {=_xlfn.IFS(BN24="None", $C25:$G29*0, BN24="Horizontal Flip", INDEX($C25:$G29, _xlfn.SEQUENCE(5), 6 - _xlfn.SEQUENCE(1,5)), BN24="Vertical Flip", INDEX($C25:$G29, 6 - _xlfn.SEQUENCE(5), _xlfn.SEQUENCE(1,5)), BN24="180 Rotation", INDEX($C25:$G29, 6 - _xlfn.SEQUENCE(5), 6 - _xlfn.SEQUENCE(1,5)), BN24="90 CW", INDEX($C25:$G29, 6 - _xlfn.SEQUENCE(1,5), _xlfn.SEQUENCE(5)), BN24="90 CCW", INDEX($C25:$G29, _xlfn.SEQUENCE(1,5), 6 - _xlfn.SEQUENCE(5)), BN24="Shift Up", IF(_xlfn.SEQUENCE(5)+1<=5, INDEX($C25:$G29, _xlfn.SEQUENCE(5)+1, _xlfn.SEQUENCE(1,5)), 0), BN24="Shift Down", IF(_xlfn.SEQUENCE(5)-1>=1, INDEX($C25:$G29, _xlfn.SEQUENCE(5)-1, _xlfn.SEQUENCE(1,5)), 0), BN24="Shift Left", IF(_xlfn.SEQUENCE(1,5)+1<=5, INDEX($C25:$G29, _xlfn.SEQUENCE(5), _xlfn.SEQUENCE(1,5)+1),0), BN24= "Shift Right", IF(_xlfn.SEQUENCE(1,5)-1>=1, INDEX($C25:$G29, _xlfn.SEQUENCE(5), _xlfn.SEQUENCE(1,5)-1), 0), BN24="Noise", _xlfn.MAP($C25:$G29 + (_xlfn.RANDARRAY(ROWS($C25:$G29), COLUMNS($C25:$G29)) - 0.5) * 0.4, _xlfn.LAMBDA(_xlpm.x, MAX(0, MIN(1, _xlpm.x)))))} -> 0.38298016 | BO25: 0.81418053 | BP25: 1 | BQ25: 1 | BR25: 0.23211242 | BU25: {=_xlfn.IFS(BU24="None", $C25:$G29*0, BU24="Horizontal Flip", INDEX($C25:$G29, _xlfn.SEQUENCE(5), 6 - _xlfn.SEQUENCE(1,5)), BU24="Vertical Flip", INDEX($C25:$G29, 6 - _xlfn.SEQUENCE(5), _xlfn.SEQUENCE(1,5)), BU24="180 Rotation", INDEX($C25:$G29, 6 - _xlfn.SEQUENCE(5), 6 - _xlfn.SEQUENCE(1,5)), BU24="90 CW", INDEX($C25:$G29, 6 - _xlfn.SEQUENCE(1,5), _xlfn.SEQUENCE(5)), BU24="90 CCW", INDEX($C25:$G29, _xlfn.SEQUENCE(1,5), 6 - _xlfn.SEQUENCE(5)), BU24="Shift Up", IF(_xlfn.SEQUENCE(5)+1<=5, INDEX($C25:$G29, _xlfn.SEQUENCE(5)+1, _xlfn.SEQUENCE(1,5)), 0), BU24="Shift Down", IF(_xlfn.SEQUENCE(5)-1>=1, INDEX($C25:$G29, _xlfn.SEQUENCE(5)-1, _xlfn.SEQUENCE(1,5)), 0), BU24="Shift Left", IF(_xlfn.SEQUENCE(1,5)+1<=5, INDEX($C25:$G29, _xlfn.SEQUENCE(5), _xlfn.SEQUENCE(1,5)+1),0), BU24= "Shift Right", IF(_xlfn.SEQUENCE(1,5)-1>=1, INDEX($C25:$G29, _xlfn.SEQUENCE(5), _xlfn.SEQUENCE(1,5)-1), 0), BU24="Noise", _xlfn.MAP($C25:$G29 + (_xlfn.RANDARRAY(ROWS($C25:$G29), COLUMNS($C25:$G29)) - 0.5) * 0.4, _xlfn.LAMBDA(_xlpm.x, MAX(0, MIN(1, _xlpm.x)))))} -> 0.47361589 | BV25: 0.24288144 | BW25: 0.41181979 | BX25: 0.5769979 | BY25: 0.45498379
C26: 0.5769979 | D26: 0.38322233 | E26: 0.15720976 | F26: 1 | G26: 0.30909224 | J26: 0.41181979 | K26: 1 | L26: 1 | M26: 1 | N26: 0.45743299 | Q26: 0.24288144 | R26: 0.43554736 | S26: 0.17145441 | T26: 1 | U26: 0.57160394 | X26: 0.57160394 | Y26: 1 | Z26: 0.17145441 | AA26: 0.43554736 | AB26: 0.24288144 | AE26: 0.30909224 | AF26: 1 | AG26: 0.15720976 | AH26: 0.38322233 | AI26: 0.5769979 | AL26: 1 | AM26: 1 | AN26: 1 | AO26: 1 | AP26: 1 | AS26: 0.45498379 | AT26: 1 | AU26: 1 | AV26: 1 | AW26: 0.2291328 | AZ26: 0 | BA26: 0.5769979 | BB26: 0.38322233 | BC26: 0.15720976 | BD26: 1 | BG26: 0.38322233 | BH26: 0.15720976 | BI26: 1 | BJ26: 0.30909224 | BK26: 0 | BN26: 0.49375778 | BO26: 0.35914579 | BP26: 0.097925834 | BQ26: 0.95137022 | BR26: 0.29595643 | BU26: 1 | BV26: 0.43554736 | BW26: 1 | BX26: 0.38322233 | BY26: 1
C27: 0.41181979 | D27: 1 | E27: 1 | F27: 1 | G27: 0.45743299 | J27: 0.24288144 | K27: 0.43554736 | L27: 0.17145441 | M27: 1 | N27: 0.57160394 | Q27: 0.41181979 | R27: 1 | S27: 1 | T27: 1 | U27: 0.45743299 | X27: 0.45743299 | Y27: 1 | Z27: 1 | AA27: 1 | AB27: 0.41181979 | AE27: 0.45743299 | AF27: 1 | AG27: 1 | AH27: 1 | AI27: 0.41181979 | AL27: 1 | AM27: 0.15720976 | AN27: 1 | AO27: 0.17145441 | AP27: 1 | AS27: 0.5769979 | AT27: 0.38322233 | AU27: 0.15720976 | AV27: 1 | AW27: 0.30909224 | AZ27: 0 | BA27: 0.41181979 | BB27: 1 | BC27: 1 | BD27: 1 | BG27: 1 | BH27: 1 | BI27: 1 | BJ27: 0.45743299 | BK27: 0 | BN27: 0.53166268 | BO27: 0.99976059 | BP27: 1 | BQ27: 0.91872386 | BR27: 0.26493492 | BU27: 1 | BV27: 0.17145441 | BW27: 1 | BX27: 0.15720976 | BY27: 1
